{"cells": [{"metadata": {}, "cell_type": "code", "source": "\nfrom ibmdbpy import IdaDataBase, IdaDataFrame\n\n# @hidden_cell\n# This connection object is used to access your data and contains your credentials.\n# You might want to remove those credentials before you share your notebook.\nidadb_b17dd4d9dff84b519a9e627f3bec50c4 = IdaDataBase(dsn='DASHDB;Database=BLUDB;Hostname=dashdb-txn-sbox-yp-dal09-08.services.dal.bluemix.net;Port=50000;PROTOCOL=TCPIP;UID=sdc18363;PWD=g6tf3xjbqm+p2hxd')\n\nsql_data = IdaDataFrame(idadb_b17dd4d9dff84b519a9e627f3bec50c4, 'SDC18363.TRANSLATIONS').as_dataframe()\nsql_data.head()\n\n# You can close the database connection with the following code. Please keep the comment line with the @hidden_cell tag,\n# because the close function displays parts of the credentials.\n# @hidden_cell\n# idadb_b17dd4d9dff84b519a9e627f3bec50c4.close()\n# To learn more about the ibmdby package, please read the documentation: http://pythonhosted.org/ibmdbpy/\n", "execution_count": 1, "outputs": [{"output_type": "execute_result", "execution_count": 1, "data": {"text/plain": "  Customer Type               Comments Identified_Language  \\\n0       Passive  Amenity Kit: Comments                  fr   \n1     Detractor  Amenity Kit: Comments                  en   \n2     Detractor  Amenity Kit: Comments                  fr   \n3     Detractor  Amenity Kit: Comments                  en   \n4     Detractor  Amenity Kit: Comments                  en   \n\n                                 Translated_Language  \\\n0                                         Very well.   \n1                               Not taking well kids   \n2  Up to the detail we see the regression of Air ...   \n3  I appreciate this kit in economy. It is a welc...   \n4                                           Nothing    \n\n                                            Response  \\\n0                                         Tr\u00e8s bien.   \n1                               Not taking well kids   \n2  jusque dans le d\u00e9tail nous voyons la r\u00e9gressio...   \n3  I appreciate this kit in economy. It is a welc...   \n4                                           Nothing    \n\n                    Categorisation Sentiment   Sector Flight No Flight Date  \\\n0                       Compliment  Positive  MRU-CDG    NK0034  26/11/2018   \n1             No adequate products  Negative  MRU-MAA    NK0746  26/11/2018   \n2  Poor quality/ Very dissatisfied  Negative  BOM-MRU    NK0749  26/11/2018   \n3                       Compliment  Positive  SIN-MRU    NK0647  27/11/2018   \n4                             None   Neutral  MRU-BOM    NK0748  27/11/2018   \n\n  Cabin Class Seat No Aircraft Version Tail No FFP Member  Gender    Age  \\\n0     ECONOMY    039E             359C   3BNBQ         NO    Male  26-34   \n1     ECONOMY    None             343E   3BNBJ         NO    Male  35-44   \n2     ECONOMY    011C             343E   3BNBI         NO  Female  45-54   \n3     ECONOMY    016B              332   3BNBM         NO  Female  55-64   \n4     ECONOMY    026H             343C   3BNAU        YES    Male  45-54   \n\n     Country  \n0     France  \n1  Mauritius  \n2  Mauritius  \n3  Mauritius  \n4      India  ", "text/html": "<div>\n<style scoped>\n    .dataframe tbody tr th:only-of-type {\n        vertical-align: middle;\n    }\n\n    .dataframe tbody tr th {\n        vertical-align: top;\n    }\n\n    .dataframe thead th {\n        text-align: right;\n    }\n</style>\n<table border=\"1\" class=\"dataframe\">\n  <thead>\n    <tr style=\"text-align: right;\">\n      <th></th>\n      <th>Customer Type</th>\n      <th>Comments</th>\n      <th>Identified_Language</th>\n      <th>Translated_Language</th>\n      <th>Response</th>\n      <th>Categorisation</th>\n      <th>Sentiment</th>\n      <th>Sector</th>\n      <th>Flight No</th>\n      <th>Flight Date</th>\n      <th>Cabin Class</th>\n      <th>Seat No</th>\n      <th>Aircraft Version</th>\n      <th>Tail No</th>\n      <th>FFP Member</th>\n      <th>Gender</th>\n      <th>Age</th>\n      <th>Country</th>\n    </tr>\n  </thead>\n  <tbody>\n    <tr>\n      <th>0</th>\n      <td>Passive</td>\n      <td>Amenity Kit: Comments</td>\n      <td>fr</td>\n      <td>Very well.</td>\n      <td>Tr\u00e8s bien.</td>\n      <td>Compliment</td>\n      <td>Positive</td>\n      <td>MRU-CDG</td>\n      <td>NK0034</td>\n      <td>26/11/2018</td>\n      <td>ECONOMY</td>\n      <td>039E</td>\n      <td>359C</td>\n      <td>3BNBQ</td>\n      <td>NO</td>\n      <td>Male</td>\n      <td>26-34</td>\n      <td>France</td>\n    </tr>\n    <tr>\n      <th>1</th>\n      <td>Detractor</td>\n      <td>Amenity Kit: Comments</td>\n      <td>en</td>\n      <td>Not taking well kids</td>\n      <td>Not taking well kids</td>\n      <td>No adequate products</td>\n      <td>Negative</td>\n      <td>MRU-MAA</td>\n      <td>NK0746</td>\n      <td>26/11/2018</td>\n      <td>ECONOMY</td>\n      <td>None</td>\n      <td>343E</td>\n      <td>3BNBJ</td>\n      <td>NO</td>\n      <td>Male</td>\n      <td>35-44</td>\n      <td>Mauritius</td>\n    </tr>\n    <tr>\n      <th>2</th>\n      <td>Detractor</td>\n      <td>Amenity Kit: Comments</td>\n      <td>fr</td>\n      <td>Up to the detail we see the regression of Air ...</td>\n      <td>jusque dans le d\u00e9tail nous voyons la r\u00e9gressio...</td>\n      <td>Poor quality/ Very dissatisfied</td>\n      <td>Negative</td>\n      <td>BOM-MRU</td>\n      <td>NK0749</td>\n      <td>26/11/2018</td>\n      <td>ECONOMY</td>\n      <td>011C</td>\n      <td>343E</td>\n      <td>3BNBI</td>\n      <td>NO</td>\n      <td>Female</td>\n      <td>45-54</td>\n      <td>Mauritius</td>\n    </tr>\n    <tr>\n      <th>3</th>\n      <td>Detractor</td>\n      <td>Amenity Kit: Comments</td>\n      <td>en</td>\n      <td>I appreciate this kit in economy. It is a welc...</td>\n      <td>I appreciate this kit in economy. It is a welc...</td>\n      <td>Compliment</td>\n      <td>Positive</td>\n      <td>SIN-MRU</td>\n      <td>NK0647</td>\n      <td>27/11/2018</td>\n      <td>ECONOMY</td>\n      <td>016B</td>\n      <td>332</td>\n      <td>3BNBM</td>\n      <td>NO</td>\n      <td>Female</td>\n      <td>55-64</td>\n      <td>Mauritius</td>\n    </tr>\n    <tr>\n      <th>4</th>\n      <td>Detractor</td>\n      <td>Amenity Kit: Comments</td>\n      <td>en</td>\n      <td>Nothing</td>\n      <td>Nothing</td>\n      <td>None</td>\n      <td>Neutral</td>\n      <td>MRU-BOM</td>\n      <td>NK0748</td>\n      <td>27/11/2018</td>\n      <td>ECONOMY</td>\n      <td>026H</td>\n      <td>343C</td>\n      <td>3BNAU</td>\n      <td>YES</td>\n      <td>Male</td>\n      <td>45-54</td>\n      <td>India</td>\n    </tr>\n  </tbody>\n</table>\n</div>"}, "metadata": {}}]}, {"metadata": {}, "cell_type": "code", "source": "# Checking Shape of dataframe(Number of records & Coulmns Available in Dataframe)\nsql_data.shape", "execution_count": 2, "outputs": [{"output_type": "execute_result", "execution_count": 2, "data": {"text/plain": "(5347, 18)"}, "metadata": {}}]}, {"metadata": {}, "cell_type": "code", "source": "#upgrade Watson Packages\n! pip install --upgrade \"ibm-watson>=4.3.0\"", "execution_count": 3, "outputs": [{"output_type": "stream", "text": "Collecting ibm-watson>=4.3.0\n\u001b[?25l  Downloading https://files.pythonhosted.org/packages/36/01/a05ed4557dbeebd95b3dcda2d01ae66f94b1aa4700bc4a8a8713c77cfeda/ibm-watson-4.4.1.tar.gz (366kB)\n\u001b[K     |\u2588\u2588\u2588\u2588\u2588\u2588\u2588\u2588\u2588\u2588\u2588\u2588\u2588\u2588\u2588\u2588\u2588\u2588\u2588\u2588\u2588\u2588\u2588\u2588\u2588\u2588\u2588\u2588\u2588\u2588\u2588\u2588| 368kB 8.9MB/s eta 0:00:01\n\u001b[?25hRequirement already satisfied, skipping upgrade: requests<3.0,>=2.0 in /opt/conda/envs/Python36/lib/python3.6/site-packages (from ibm-watson>=4.3.0) (2.21.0)\nRequirement already satisfied, skipping upgrade: python_dateutil>=2.5.3 in /opt/conda/envs/Python36/lib/python3.6/site-packages (from ibm-watson>=4.3.0) (2.7.5)\nCollecting websocket-client==0.48.0 (from ibm-watson>=4.3.0)\n\u001b[?25l  Downloading https://files.pythonhosted.org/packages/8a/a1/72ef9aa26cfe1a75cee09fc1957e4723add9de098c15719416a1ee89386b/websocket_client-0.48.0-py2.py3-none-any.whl (198kB)\n\u001b[K     |\u2588\u2588\u2588\u2588\u2588\u2588\u2588\u2588\u2588\u2588\u2588\u2588\u2588\u2588\u2588\u2588\u2588\u2588\u2588\u2588\u2588\u2588\u2588\u2588\u2588\u2588\u2588\u2588\u2588\u2588\u2588\u2588| 204kB 29.2MB/s eta 0:00:01\n\u001b[?25hCollecting ibm_cloud_sdk_core==1.5.1 (from ibm-watson>=4.3.0)\n  Downloading https://files.pythonhosted.org/packages/b7/f6/10d5271c807d73d236e6ae07b68035fed78b28b5ab836704d34097af3986/ibm-cloud-sdk-core-1.5.1.tar.gz\nRequirement already satisfied, skipping upgrade: chardet<3.1.0,>=3.0.2 in /opt/conda/envs/Python36/lib/python3.6/site-packages (from requests<3.0,>=2.0->ibm-watson>=4.3.0) (3.0.4)\nRequirement already satisfied, skipping upgrade: urllib3<1.25,>=1.21.1 in /opt/conda/envs/Python36/lib/python3.6/site-packages (from requests<3.0,>=2.0->ibm-watson>=4.3.0) (1.24.1)\nRequirement already satisfied, skipping upgrade: certifi>=2017.4.17 in /opt/conda/envs/Python36/lib/python3.6/site-packages (from requests<3.0,>=2.0->ibm-watson>=4.3.0) (2020.4.5.1)\nRequirement already satisfied, skipping upgrade: idna<2.9,>=2.5 in /opt/conda/envs/Python36/lib/python3.6/site-packages (from requests<3.0,>=2.0->ibm-watson>=4.3.0) (2.8)\nRequirement already satisfied, skipping upgrade: six>=1.5 in /opt/conda/envs/Python36/lib/python3.6/site-packages (from python_dateutil>=2.5.3->ibm-watson>=4.3.0) (1.12.0)\nCollecting PyJWT>=1.7.1 (from ibm_cloud_sdk_core==1.5.1->ibm-watson>=4.3.0)\n  Downloading https://files.pythonhosted.org/packages/87/8b/6a9f14b5f781697e51259d81657e6048fd31a113229cf346880bb7545565/PyJWT-1.7.1-py2.py3-none-any.whl\nBuilding wheels for collected packages: ibm-watson, ibm-cloud-sdk-core\n  Building wheel for ibm-watson (setup.py) ... \u001b[?25ldone\n\u001b[?25h  Stored in directory: /home/dsxuser/.cache/pip/wheels/73/21/91/61a59270c329be2edc947c69871c25c50bf7dd87ebbfe07cdc\n  Building wheel for ibm-cloud-sdk-core (setup.py) ... \u001b[?25ldone\n\u001b[?25h  Stored in directory: /home/dsxuser/.cache/pip/wheels/6a/42/50/f96888116b329578304f9dda4693cef6f3e76e18272d22cb6c\nSuccessfully built ibm-watson ibm-cloud-sdk-core\nInstalling collected packages: websocket-client, PyJWT, ibm-cloud-sdk-core, ibm-watson\nSuccessfully installed PyJWT-1.7.1 ibm-cloud-sdk-core-1.5.1 ibm-watson-4.4.1 websocket-client-0.48.0\n", "name": "stdout"}]}, {"metadata": {}, "cell_type": "code", "source": "# Import libraries for Sentiments extraction using Watson Language Understanding Service From IBM Cloud\n#import pandas as pd\n#import json\nfrom ibm_watson import NaturalLanguageUnderstandingV1\nfrom ibm_cloud_sdk_core.authenticators import IAMAuthenticator\nfrom ibm_watson.natural_language_understanding_v1 import Features, EntitiesOptions, KeywordsOptions, ConceptsOptions, EmotionOptions, SentimentOptions\nfrom ibm_watson import ApiException\nimport operator", "execution_count": 4, "outputs": []}, {"metadata": {}, "cell_type": "code", "source": "# Adding Watson Natural Language Understanding credentials \nauthenticator = IAMAuthenticator('A1GtyTmtA04fXb6pULb4RkEjZ9bVPJsMUie4YZA8j1jf')\nnatural_language_understanding = NaturalLanguageUnderstandingV1(version='2019-07-12',authenticator=authenticator\n)\n\nnatural_language_understanding.set_service_url('https://api.eu-gb.natural-language-understanding.watson.cloud.ibm.com/instances/71485e6d-eb98-4ade-bf42-904a7765003a')", "execution_count": 5, "outputs": []}, {"metadata": {}, "cell_type": "code", "source": "# Dummy List's For Sentiment Extraction\nsentiment=[]\nsentiment_score=[]\nkeywords=[]\nkeywords_label=[]\nkeywords_relevance=[]\n\n\nemotion_sadness=[]\nemotion_joy=[]\nemotion_fear=[]\nemotion_disgust=[]\nemotion_anger=[]\n\n\nconcepts_text=[]\nconcepts_relevance=[]", "execution_count": 6, "outputs": []}, {"metadata": {}, "cell_type": "code", "source": "from tqdm import tqdm", "execution_count": 7, "outputs": []}, {"metadata": {}, "cell_type": "code", "source": "for i in tqdm(range(0,len(sql_data['Translated_Language']))):\n    try:\n        response = natural_language_understanding.analyze(text=str(sql_data['Translated_Language'][i]),\n        language='en',                          \n        features=Features(\n        entities=EntitiesOptions(emotion=True, sentiment=True, limit=1),\n        keywords=KeywordsOptions(emotion=True, sentiment=True,limit=1),\n        concepts=ConceptsOptions(limit=1),\n        emotion=EmotionOptions(document=True),\n        sentiment=SentimentOptions(document=True))).get_result()\n\n     #sentiments list collection    \n        try:\n            (response['sentiment']['document']['label']) != ''  \n            sentiment.append(response['sentiment']['document']['label'])   \n        except:\n            sentiment.append('')\n        try:   \n            response['sentiment']['document']['score'] != ''\n            sentiment_score.append(response['sentiment']['document']['score'])    \n        except:       \n            sentiment_score.append('')\n\n    #keywords list collections\n        try:\n            (response['keywords'][0]['text']) != ''       \n            keywords.append((response['keywords'][0]['text']))\n        except:        \n            keywords.append('')\n        try:        \n            (response['keywords'][0]['sentiment']['label']) != ''     \n            keywords_label.append(response['keywords'][0]['sentiment']['label'])\n        except:        \n            keywords_label.append('')\n\n        try:           \n            (response['keywords'][0]['relevance']) != ''         \n            keywords_relevance.append(response['keywords'][0]['relevance'])\n        except:        \n            keywords_relevance.append('')\n\n    #emotion extraction\n\n        try:\n            (response['emotion']) != []      \n            emotion_sadness.append(response['emotion']['document']['emotion']['sadness'])\n            emotion_anger.append(response['emotion']['document']['emotion']['anger'])\n            emotion_joy.append(response['emotion']['document']['emotion']['joy'])\n            emotion_disgust.append(response['emotion']['document']['emotion']['disgust'])\n            emotion_fear.append(response['emotion']['document']['emotion']['fear'])\n\n        except:\n            emotion_anger.append('')\n            emotion_disgust.append('')\n            emotion_fear.append('')\n            emotion_joy.append('')\n            emotion_sadness.append('')\n\n    #extracting concepts\n        try:\n            response['concepts'] != []\n            concepts_text.append(response['concepts'][0]['text'])\n#             print(concepts_text)\n            concepts_relevance.append(response['concepts'][0]['relevance'])\n#             print(concepts_relevance)\n                \n        except:\n            \n            concepts_relevance.append('')\n            concepts_text.append('')\n    except:\n#         print(False + i)\n        sentiment.append('')\n        sentiment_score.append('')\n        keywords.append('')\n        keywords_label.append('')\n        keywords_relevance.append('')\n\n\n        emotion_sadness.append('')\n        emotion_joy.append('')\n        emotion_fear.append('')\n        emotion_disgust.append('')\n        emotion_anger.append('')\n\n\n        concepts_text.append('')\n        concepts_relevance.append('')", "execution_count": null, "outputs": [{"output_type": "stream", "text": " 21%|\u2588\u2588        | 1108/5347 [07:46<24:51,  2.84it/s] ERROR:root:invalid request: content is empty\nTraceback (most recent call last):\n  File \"/opt/conda/envs/Python36/lib/python3.6/site-packages/ibm_cloud_sdk_core/base_service.py\", line 229, in send\n    response.status_code, error_message, http_response=response)\nibm_cloud_sdk_core.api_exception.ApiException: Error: invalid request: content is empty, Code: 400 , X-global-transaction-id: 10553ae2636675db648c053c32986121\n 33%|\u2588\u2588\u2588\u258e      | 1790/5347 [12:34<25:59,  2.28it/s]ERROR:root:Error in service call\nTraceback (most recent call last):\n  File \"/opt/conda/envs/Python36/lib/python3.6/site-packages/urllib3/connectionpool.py\", line 377, in _make_request\n    httplib_response = conn.getresponse(buffering=True)\nTypeError: getresponse() got an unexpected keyword argument 'buffering'\n\nDuring handling of the above exception, another exception occurred:\n\nTraceback (most recent call last):\n  File \"/opt/conda/envs/Python36/lib/python3.6/site-packages/urllib3/contrib/pyopenssl.py\", line 294, in recv_into\n    return self.connection.recv_into(*args, **kwargs)\n  File \"/opt/conda/envs/Python36/lib/python3.6/site-packages/OpenSSL/SSL.py\", line 1822, in recv_into\n    self._raise_ssl_error(self._ssl, result)\n  File \"/opt/conda/envs/Python36/lib/python3.6/site-packages/OpenSSL/SSL.py\", line 1622, in _raise_ssl_error\n    raise WantReadError()\nOpenSSL.SSL.WantReadError\n\nDuring handling of the above exception, another exception occurred:\n\nTraceback (most recent call last):\n  File \"/opt/conda/envs/Python36/lib/python3.6/site-packages/ibm_cloud_sdk_core/base_service.py\", line 208, in send\n    response = requests.request(**request, cookies=self.jar, **kwargs)\n  File \"/opt/conda/envs/Python36/lib/python3.6/site-packages/requests/api.py\", line 60, in request\n    return session.request(method=method, url=url, **kwargs)\n  File \"/opt/conda/envs/Python36/lib/python3.6/site-packages/requests/sessions.py\", line 533, in request\n    resp = self.send(prep, **send_kwargs)\n  File \"/opt/conda/envs/Python36/lib/python3.6/site-packages/requests/sessions.py\", line 646, in send\n    r = adapter.send(request, **kwargs)\n  File \"/opt/conda/envs/Python36/lib/python3.6/site-packages/requests/adapters.py\", line 449, in send\n    timeout=timeout\n  File \"/opt/conda/envs/Python36/lib/python3.6/site-packages/urllib3/connectionpool.py\", line 600, in urlopen\n    chunked=chunked)\n  File \"/opt/conda/envs/Python36/lib/python3.6/site-packages/urllib3/connectionpool.py\", line 380, in _make_request\n    httplib_response = conn.getresponse()\n  File \"/opt/conda/envs/Python36/lib/python3.6/http/client.py\", line 1346, in getresponse\n    response.begin()\n  File \"/opt/conda/envs/Python36/lib/python3.6/http/client.py\", line 307, in begin\n    version, status, reason = self._read_status()\n  File \"/opt/conda/envs/Python36/lib/python3.6/http/client.py\", line 268, in _read_status\n    line = str(self.fp.readline(_MAXLINE + 1), \"iso-8859-1\")\n  File \"/opt/conda/envs/Python36/lib/python3.6/socket.py\", line 586, in readinto\n    return self._sock.recv_into(b)\n  File \"/opt/conda/envs/Python36/lib/python3.6/site-packages/urllib3/contrib/pyopenssl.py\", line 306, in recv_into\n    if not util.wait_for_read(self.socket, self.socket.gettimeout()):\n  File \"/opt/conda/envs/Python36/lib/python3.6/site-packages/urllib3/util/wait.py\", line 143, in wait_for_read\n    return wait_for_socket(sock, read=True, timeout=timeout)\n  File \"/opt/conda/envs/Python36/lib/python3.6/site-packages/urllib3/util/wait.py\", line 104, in poll_wait_for_socket\n    return bool(_retry_on_intr(do_poll, timeout))\n  File \"/opt/conda/envs/Python36/lib/python3.6/site-packages/urllib3/util/wait.py\", line 42, in _retry_on_intr\n    return fn(timeout)\n  File \"/opt/conda/envs/Python36/lib/python3.6/site-packages/urllib3/util/wait.py\", line 102, in do_poll\n    return poll_obj.poll(t)\nKeyboardInterrupt\n 71%|\u2588\u2588\u2588\u2588\u2588\u2588\u2588   | 3803/5347 [27:06<10:44,  2.40it/s]ERROR:root:Forbidden\nTraceback (most recent call last):\n  File \"/opt/conda/envs/Python36/lib/python3.6/site-packages/ibm_cloud_sdk_core/base_service.py\", line 229, in send\n    response.status_code, error_message, http_response=response)\nibm_cloud_sdk_core.api_exception.ApiException: Error: Forbidden, Code: 403\n 71%|\u2588\u2588\u2588\u2588\u2588\u2588\u2588   | 3804/5347 [27:07<12:48,  2.01it/s]ERROR:root:Forbidden\nTraceback (most recent call last):\n  File \"/opt/conda/envs/Python36/lib/python3.6/site-packages/ibm_cloud_sdk_core/base_service.py\", line 229, in send\n    response.status_code, error_message, http_response=response)\nibm_cloud_sdk_core.api_exception.ApiException: Error: Forbidden, Code: 403\n 71%|\u2588\u2588\u2588\u2588\u2588\u2588\u2588   | 3805/5347 [27:07<10:26,  2.46it/s]ERROR:root:Forbidden\nTraceback (most recent call last):\n  File \"/opt/conda/envs/Python36/lib/python3.6/site-packages/ibm_cloud_sdk_core/base_service.py\", line 229, in send\n    response.status_code, error_message, http_response=response)\nibm_cloud_sdk_core.api_exception.ApiException: Error: Forbidden, Code: 403\n 71%|\u2588\u2588\u2588\u2588\u2588\u2588\u2588   | 3806/5347 [27:08<08:48,  2.92it/s]ERROR:root:Forbidden\nTraceback (most recent call last):\n  File \"/opt/conda/envs/Python36/lib/python3.6/site-packages/ibm_cloud_sdk_core/base_service.py\", line 229, in send\n    response.status_code, error_message, http_response=response)\nibm_cloud_sdk_core.api_exception.ApiException: Error: Forbidden, Code: 403\n 71%|\u2588\u2588\u2588\u2588\u2588\u2588\u2588   | 3807/5347 [27:08<07:26,  3.45it/s]ERROR:root:Forbidden\nTraceback (most recent call last):\n  File \"/opt/conda/envs/Python36/lib/python3.6/site-packages/ibm_cloud_sdk_core/base_service.py\", line 229, in send\n    response.status_code, error_message, http_response=response)\nibm_cloud_sdk_core.api_exception.ApiException: Error: Forbidden, Code: 403\n 71%|\u2588\u2588\u2588\u2588\u2588\u2588\u2588   | 3808/5347 [27:08<06:38,  3.86it/s]ERROR:root:Forbidden\nTraceback (most recent call last):\n  File \"/opt/conda/envs/Python36/lib/python3.6/site-packages/ibm_cloud_sdk_core/base_service.py\", line 229, in send\n    response.status_code, error_message, http_response=response)\nibm_cloud_sdk_core.api_exception.ApiException: Error: Forbidden, Code: 403\n 71%|\u2588\u2588\u2588\u2588\u2588\u2588\u2588   | 3809/5347 [27:08<06:15,  4.10it/s]ERROR:root:Forbidden\nTraceback (most recent call last):\n  File \"/opt/conda/envs/Python36/lib/python3.6/site-packages/ibm_cloud_sdk_core/base_service.py\", line 229, in send\n    response.status_code, error_message, http_response=response)\nibm_cloud_sdk_core.api_exception.ApiException: Error: Forbidden, Code: 403\n 71%|\u2588\u2588\u2588\u2588\u2588\u2588\u2588\u258f  | 3810/5347 [27:08<05:55,  4.32it/s]ERROR:root:Forbidden\nTraceback (most recent call last):\n  File \"/opt/conda/envs/Python36/lib/python3.6/site-packages/ibm_cloud_sdk_core/base_service.py\", line 229, in send\n    response.status_code, error_message, http_response=response)\nibm_cloud_sdk_core.api_exception.ApiException: Error: Forbidden, Code: 403\n 71%|\u2588\u2588\u2588\u2588\u2588\u2588\u2588\u258f  | 3811/5347 [27:08<05:35,  4.58it/s]ERROR:root:Forbidden\nTraceback (most recent call last):\n  File \"/opt/conda/envs/Python36/lib/python3.6/site-packages/ibm_cloud_sdk_core/base_service.py\", line 229, in send\n    response.status_code, error_message, http_response=response)\nibm_cloud_sdk_core.api_exception.ApiException: Error: Forbidden, Code: 403\n 71%|\u2588\u2588\u2588\u2588\u2588\u2588\u2588\u258f  | 3812/5347 [27:09<05:29,  4.66it/s]ERROR:root:Forbidden\nTraceback (most recent call last):\n  File \"/opt/conda/envs/Python36/lib/python3.6/site-packages/ibm_cloud_sdk_core/base_service.py\", line 229, in send\n    response.status_code, error_message, http_response=response)\nibm_cloud_sdk_core.api_exception.ApiException: Error: Forbidden, Code: 403\n 71%|\u2588\u2588\u2588\u2588\u2588\u2588\u2588\u258f  | 3813/5347 [27:09<05:15,  4.86it/s]ERROR:root:Forbidden\nTraceback (most recent call last):\n  File \"/opt/conda/envs/Python36/lib/python3.6/site-packages/ibm_cloud_sdk_core/base_service.py\", line 229, in send\n    response.status_code, error_message, http_response=response)\nibm_cloud_sdk_core.api_exception.ApiException: Error: Forbidden, Code: 403\n 71%|\u2588\u2588\u2588\u2588\u2588\u2588\u2588\u258f  | 3814/5347 [27:09<05:13,  4.89it/s]ERROR:root:Forbidden\nTraceback (most recent call last):\n  File \"/opt/conda/envs/Python36/lib/python3.6/site-packages/ibm_cloud_sdk_core/base_service.py\", line 229, in send\n    response.status_code, error_message, http_response=response)\nibm_cloud_sdk_core.api_exception.ApiException: Error: Forbidden, Code: 403\n", "name": "stderr"}, {"output_type": "stream", "text": " 71%|\u2588\u2588\u2588\u2588\u2588\u2588\u2588\u258f  | 3815/5347 [27:09<05:00,  5.10it/s]ERROR:root:Forbidden\nTraceback (most recent call last):\n  File \"/opt/conda/envs/Python36/lib/python3.6/site-packages/ibm_cloud_sdk_core/base_service.py\", line 229, in send\n    response.status_code, error_message, http_response=response)\nibm_cloud_sdk_core.api_exception.ApiException: Error: Forbidden, Code: 403\n 71%|\u2588\u2588\u2588\u2588\u2588\u2588\u2588\u258f  | 3816/5347 [27:09<04:49,  5.29it/s]ERROR:root:Forbidden\nTraceback (most recent call last):\n  File \"/opt/conda/envs/Python36/lib/python3.6/site-packages/ibm_cloud_sdk_core/base_service.py\", line 229, in send\n    response.status_code, error_message, http_response=response)\nibm_cloud_sdk_core.api_exception.ApiException: Error: Forbidden, Code: 403\n 71%|\u2588\u2588\u2588\u2588\u2588\u2588\u2588\u258f  | 3817/5347 [27:10<07:30,  3.40it/s]ERROR:root:Forbidden\nTraceback (most recent call last):\n  File \"/opt/conda/envs/Python36/lib/python3.6/site-packages/ibm_cloud_sdk_core/base_service.py\", line 229, in send\n    response.status_code, error_message, http_response=response)\nibm_cloud_sdk_core.api_exception.ApiException: Error: Forbidden, Code: 403\n 71%|\u2588\u2588\u2588\u2588\u2588\u2588\u2588\u258f  | 3818/5347 [27:10<09:26,  2.70it/s]ERROR:root:Forbidden\nTraceback (most recent call last):\n  File \"/opt/conda/envs/Python36/lib/python3.6/site-packages/ibm_cloud_sdk_core/base_service.py\", line 229, in send\n    response.status_code, error_message, http_response=response)\nibm_cloud_sdk_core.api_exception.ApiException: Error: Forbidden, Code: 403\n 71%|\u2588\u2588\u2588\u2588\u2588\u2588\u2588\u258f  | 3819/5347 [27:11<08:03,  3.16it/s]ERROR:root:Forbidden\nTraceback (most recent call last):\n  File \"/opt/conda/envs/Python36/lib/python3.6/site-packages/ibm_cloud_sdk_core/base_service.py\", line 229, in send\n    response.status_code, error_message, http_response=response)\nibm_cloud_sdk_core.api_exception.ApiException: Error: Forbidden, Code: 403\n 71%|\u2588\u2588\u2588\u2588\u2588\u2588\u2588\u258f  | 3820/5347 [27:11<07:01,  3.62it/s]ERROR:root:Forbidden\nTraceback (most recent call last):\n  File \"/opt/conda/envs/Python36/lib/python3.6/site-packages/ibm_cloud_sdk_core/base_service.py\", line 229, in send\n    response.status_code, error_message, http_response=response)\nibm_cloud_sdk_core.api_exception.ApiException: Error: Forbidden, Code: 403\n 71%|\u2588\u2588\u2588\u2588\u2588\u2588\u2588\u258f  | 3821/5347 [27:11<08:13,  3.09it/s]ERROR:root:Forbidden\nTraceback (most recent call last):\n  File \"/opt/conda/envs/Python36/lib/python3.6/site-packages/ibm_cloud_sdk_core/base_service.py\", line 229, in send\n    response.status_code, error_message, http_response=response)\nibm_cloud_sdk_core.api_exception.ApiException: Error: Forbidden, Code: 403\n 71%|\u2588\u2588\u2588\u2588\u2588\u2588\u2588\u258f  | 3822/5347 [27:11<07:04,  3.59it/s]ERROR:root:Forbidden\nTraceback (most recent call last):\n  File \"/opt/conda/envs/Python36/lib/python3.6/site-packages/ibm_cloud_sdk_core/base_service.py\", line 229, in send\n    response.status_code, error_message, http_response=response)\nibm_cloud_sdk_core.api_exception.ApiException: Error: Forbidden, Code: 403\n 71%|\u2588\u2588\u2588\u2588\u2588\u2588\u2588\u258f  | 3823/5347 [27:12<08:05,  3.14it/s]ERROR:root:Forbidden\nTraceback (most recent call last):\n  File \"/opt/conda/envs/Python36/lib/python3.6/site-packages/ibm_cloud_sdk_core/base_service.py\", line 229, in send\n    response.status_code, error_message, http_response=response)\nibm_cloud_sdk_core.api_exception.ApiException: Error: Forbidden, Code: 403\n 72%|\u2588\u2588\u2588\u2588\u2588\u2588\u2588\u258f  | 3824/5347 [27:12<09:02,  2.81it/s]ERROR:root:Forbidden\nTraceback (most recent call last):\n  File \"/opt/conda/envs/Python36/lib/python3.6/site-packages/ibm_cloud_sdk_core/base_service.py\", line 229, in send\n    response.status_code, error_message, http_response=response)\nibm_cloud_sdk_core.api_exception.ApiException: Error: Forbidden, Code: 403\n 72%|\u2588\u2588\u2588\u2588\u2588\u2588\u2588\u258f  | 3825/5347 [27:13<09:31,  2.66it/s]ERROR:root:Forbidden\nTraceback (most recent call last):\n  File \"/opt/conda/envs/Python36/lib/python3.6/site-packages/ibm_cloud_sdk_core/base_service.py\", line 229, in send\n    response.status_code, error_message, http_response=response)\nibm_cloud_sdk_core.api_exception.ApiException: Error: Forbidden, Code: 403\n 72%|\u2588\u2588\u2588\u2588\u2588\u2588\u2588\u258f  | 3826/5347 [27:13<08:08,  3.11it/s]ERROR:root:Forbidden\nTraceback (most recent call last):\n  File \"/opt/conda/envs/Python36/lib/python3.6/site-packages/ibm_cloud_sdk_core/base_service.py\", line 229, in send\n    response.status_code, error_message, http_response=response)\nibm_cloud_sdk_core.api_exception.ApiException: Error: Forbidden, Code: 403\n 72%|\u2588\u2588\u2588\u2588\u2588\u2588\u2588\u258f  | 3827/5347 [27:13<07:09,  3.54it/s]ERROR:root:Forbidden\nTraceback (most recent call last):\n  File \"/opt/conda/envs/Python36/lib/python3.6/site-packages/ibm_cloud_sdk_core/base_service.py\", line 229, in send\n    response.status_code, error_message, http_response=response)\nibm_cloud_sdk_core.api_exception.ApiException: Error: Forbidden, Code: 403\n 72%|\u2588\u2588\u2588\u2588\u2588\u2588\u2588\u258f  | 3828/5347 [27:13<06:18,  4.01it/s]ERROR:root:Forbidden\nTraceback (most recent call last):\n  File \"/opt/conda/envs/Python36/lib/python3.6/site-packages/ibm_cloud_sdk_core/base_service.py\", line 229, in send\n    response.status_code, error_message, http_response=response)\nibm_cloud_sdk_core.api_exception.ApiException: Error: Forbidden, Code: 403\n 72%|\u2588\u2588\u2588\u2588\u2588\u2588\u2588\u258f  | 3829/5347 [27:13<05:45,  4.39it/s]ERROR:root:Forbidden\nTraceback (most recent call last):\n  File \"/opt/conda/envs/Python36/lib/python3.6/site-packages/ibm_cloud_sdk_core/base_service.py\", line 229, in send\n    response.status_code, error_message, http_response=response)\nibm_cloud_sdk_core.api_exception.ApiException: Error: Forbidden, Code: 403\n 72%|\u2588\u2588\u2588\u2588\u2588\u2588\u2588\u258f  | 3830/5347 [27:14<05:36,  4.51it/s]ERROR:root:Forbidden\nTraceback (most recent call last):\n  File \"/opt/conda/envs/Python36/lib/python3.6/site-packages/ibm_cloud_sdk_core/base_service.py\", line 229, in send\n    response.status_code, error_message, http_response=response)\nibm_cloud_sdk_core.api_exception.ApiException: Error: Forbidden, Code: 403\n 72%|\u2588\u2588\u2588\u2588\u2588\u2588\u2588\u258f  | 3831/5347 [27:14<05:17,  4.78it/s]ERROR:root:Forbidden\nTraceback (most recent call last):\n  File \"/opt/conda/envs/Python36/lib/python3.6/site-packages/ibm_cloud_sdk_core/base_service.py\", line 229, in send\n    response.status_code, error_message, http_response=response)\nibm_cloud_sdk_core.api_exception.ApiException: Error: Forbidden, Code: 403\n 72%|\u2588\u2588\u2588\u2588\u2588\u2588\u2588\u258f  | 3832/5347 [27:14<05:02,  5.01it/s]ERROR:root:Forbidden\nTraceback (most recent call last):\n  File \"/opt/conda/envs/Python36/lib/python3.6/site-packages/ibm_cloud_sdk_core/base_service.py\", line 229, in send\n    response.status_code, error_message, http_response=response)\nibm_cloud_sdk_core.api_exception.ApiException: Error: Forbidden, Code: 403\n 72%|\u2588\u2588\u2588\u2588\u2588\u2588\u2588\u258f  | 3833/5347 [27:14<06:42,  3.76it/s]ERROR:root:Forbidden\nTraceback (most recent call last):\n  File \"/opt/conda/envs/Python36/lib/python3.6/site-packages/ibm_cloud_sdk_core/base_service.py\", line 229, in send\n    response.status_code, error_message, http_response=response)\nibm_cloud_sdk_core.api_exception.ApiException: Error: Forbidden, Code: 403\n 72%|\u2588\u2588\u2588\u2588\u2588\u2588\u2588\u258f  | 3834/5347 [27:15<09:31,  2.65it/s]ERROR:root:Forbidden\nTraceback (most recent call last):\n  File \"/opt/conda/envs/Python36/lib/python3.6/site-packages/ibm_cloud_sdk_core/base_service.py\", line 229, in send\n    response.status_code, error_message, http_response=response)\nibm_cloud_sdk_core.api_exception.ApiException: Error: Forbidden, Code: 403\n 72%|\u2588\u2588\u2588\u2588\u2588\u2588\u2588\u258f  | 3835/5347 [27:16<10:45,  2.34it/s]ERROR:root:Forbidden\nTraceback (most recent call last):\n  File \"/opt/conda/envs/Python36/lib/python3.6/site-packages/ibm_cloud_sdk_core/base_service.py\", line 229, in send\n    response.status_code, error_message, http_response=response)\nibm_cloud_sdk_core.api_exception.ApiException: Error: Forbidden, Code: 403\n 72%|\u2588\u2588\u2588\u2588\u2588\u2588\u2588\u258f  | 3836/5347 [27:16<09:16,  2.71it/s]ERROR:root:Forbidden\nTraceback (most recent call last):\n  File \"/opt/conda/envs/Python36/lib/python3.6/site-packages/ibm_cloud_sdk_core/base_service.py\", line 229, in send\n    response.status_code, error_message, http_response=response)\nibm_cloud_sdk_core.api_exception.ApiException: Error: Forbidden, Code: 403\n 72%|\u2588\u2588\u2588\u2588\u2588\u2588\u2588\u258f  | 3837/5347 [27:16<08:11,  3.07it/s]ERROR:root:Forbidden\nTraceback (most recent call last):\n  File \"/opt/conda/envs/Python36/lib/python3.6/site-packages/ibm_cloud_sdk_core/base_service.py\", line 229, in send\n    response.status_code, error_message, http_response=response)\nibm_cloud_sdk_core.api_exception.ApiException: Error: Forbidden, Code: 403\n", "name": "stderr"}, {"output_type": "stream", "text": " 72%|\u2588\u2588\u2588\u2588\u2588\u2588\u2588\u258f  | 3838/5347 [27:16<07:02,  3.57it/s]ERROR:root:Forbidden\nTraceback (most recent call last):\n  File \"/opt/conda/envs/Python36/lib/python3.6/site-packages/ibm_cloud_sdk_core/base_service.py\", line 229, in send\n    response.status_code, error_message, http_response=response)\nibm_cloud_sdk_core.api_exception.ApiException: Error: Forbidden, Code: 403\n 72%|\u2588\u2588\u2588\u2588\u2588\u2588\u2588\u258f  | 3839/5347 [27:17<08:10,  3.08it/s]ERROR:root:Forbidden\nTraceback (most recent call last):\n  File \"/opt/conda/envs/Python36/lib/python3.6/site-packages/ibm_cloud_sdk_core/base_service.py\", line 229, in send\n    response.status_code, error_message, http_response=response)\nibm_cloud_sdk_core.api_exception.ApiException: Error: Forbidden, Code: 403\n 72%|\u2588\u2588\u2588\u2588\u2588\u2588\u2588\u258f  | 3840/5347 [27:17<07:42,  3.26it/s]ERROR:root:Forbidden\nTraceback (most recent call last):\n  File \"/opt/conda/envs/Python36/lib/python3.6/site-packages/ibm_cloud_sdk_core/base_service.py\", line 229, in send\n    response.status_code, error_message, http_response=response)\nibm_cloud_sdk_core.api_exception.ApiException: Error: Forbidden, Code: 403\n 72%|\u2588\u2588\u2588\u2588\u2588\u2588\u2588\u258f  | 3841/5347 [27:17<08:34,  2.93it/s]ERROR:root:Forbidden\nTraceback (most recent call last):\n  File \"/opt/conda/envs/Python36/lib/python3.6/site-packages/ibm_cloud_sdk_core/base_service.py\", line 229, in send\n    response.status_code, error_message, http_response=response)\nibm_cloud_sdk_core.api_exception.ApiException: Error: Forbidden, Code: 403\n 72%|\u2588\u2588\u2588\u2588\u2588\u2588\u2588\u258f  | 3842/5347 [27:18<07:33,  3.32it/s]ERROR:root:Forbidden\nTraceback (most recent call last):\n  File \"/opt/conda/envs/Python36/lib/python3.6/site-packages/ibm_cloud_sdk_core/base_service.py\", line 229, in send\n    response.status_code, error_message, http_response=response)\nibm_cloud_sdk_core.api_exception.ApiException: Error: Forbidden, Code: 403\n 72%|\u2588\u2588\u2588\u2588\u2588\u2588\u2588\u258f  | 3843/5347 [27:18<07:05,  3.53it/s]ERROR:root:Forbidden\nTraceback (most recent call last):\n  File \"/opt/conda/envs/Python36/lib/python3.6/site-packages/ibm_cloud_sdk_core/base_service.py\", line 229, in send\n    response.status_code, error_message, http_response=response)\nibm_cloud_sdk_core.api_exception.ApiException: Error: Forbidden, Code: 403\n 72%|\u2588\u2588\u2588\u2588\u2588\u2588\u2588\u258f  | 3844/5347 [27:18<08:07,  3.09it/s]ERROR:root:Forbidden\nTraceback (most recent call last):\n  File \"/opt/conda/envs/Python36/lib/python3.6/site-packages/ibm_cloud_sdk_core/base_service.py\", line 229, in send\n    response.status_code, error_message, http_response=response)\nibm_cloud_sdk_core.api_exception.ApiException: Error: Forbidden, Code: 403\n 72%|\u2588\u2588\u2588\u2588\u2588\u2588\u2588\u258f  | 3845/5347 [27:19<08:52,  2.82it/s]ERROR:root:Forbidden\nTraceback (most recent call last):\n  File \"/opt/conda/envs/Python36/lib/python3.6/site-packages/ibm_cloud_sdk_core/base_service.py\", line 229, in send\n    response.status_code, error_message, http_response=response)\nibm_cloud_sdk_core.api_exception.ApiException: Error: Forbidden, Code: 403\n 72%|\u2588\u2588\u2588\u2588\u2588\u2588\u2588\u258f  | 3846/5347 [27:19<09:33,  2.62it/s]ERROR:root:Forbidden\nTraceback (most recent call last):\n  File \"/opt/conda/envs/Python36/lib/python3.6/site-packages/ibm_cloud_sdk_core/base_service.py\", line 229, in send\n    response.status_code, error_message, http_response=response)\nibm_cloud_sdk_core.api_exception.ApiException: Error: Forbidden, Code: 403\n 72%|\u2588\u2588\u2588\u2588\u2588\u2588\u2588\u258f  | 3847/5347 [27:19<08:15,  3.03it/s]ERROR:root:Forbidden\nTraceback (most recent call last):\n  File \"/opt/conda/envs/Python36/lib/python3.6/site-packages/ibm_cloud_sdk_core/base_service.py\", line 229, in send\n    response.status_code, error_message, http_response=response)\nibm_cloud_sdk_core.api_exception.ApiException: Error: Forbidden, Code: 403\n 72%|\u2588\u2588\u2588\u2588\u2588\u2588\u2588\u258f  | 3848/5347 [27:20<07:19,  3.41it/s]ERROR:root:Forbidden\nTraceback (most recent call last):\n  File \"/opt/conda/envs/Python36/lib/python3.6/site-packages/ibm_cloud_sdk_core/base_service.py\", line 229, in send\n    response.status_code, error_message, http_response=response)\nibm_cloud_sdk_core.api_exception.ApiException: Error: Forbidden, Code: 403\n 72%|\u2588\u2588\u2588\u2588\u2588\u2588\u2588\u258f  | 3849/5347 [27:20<08:13,  3.04it/s]ERROR:root:Forbidden\nTraceback (most recent call last):\n  File \"/opt/conda/envs/Python36/lib/python3.6/site-packages/ibm_cloud_sdk_core/base_service.py\", line 229, in send\n    response.status_code, error_message, http_response=response)\nibm_cloud_sdk_core.api_exception.ApiException: Error: Forbidden, Code: 403\n 72%|\u2588\u2588\u2588\u2588\u2588\u2588\u2588\u258f  | 3850/5347 [27:20<07:22,  3.38it/s]ERROR:root:Forbidden\nTraceback (most recent call last):\n  File \"/opt/conda/envs/Python36/lib/python3.6/site-packages/ibm_cloud_sdk_core/base_service.py\", line 229, in send\n    response.status_code, error_message, http_response=response)\nibm_cloud_sdk_core.api_exception.ApiException: Error: Forbidden, Code: 403\n 72%|\u2588\u2588\u2588\u2588\u2588\u2588\u2588\u258f  | 3851/5347 [27:20<06:46,  3.68it/s]ERROR:root:Forbidden\nTraceback (most recent call last):\n  File \"/opt/conda/envs/Python36/lib/python3.6/site-packages/ibm_cloud_sdk_core/base_service.py\", line 229, in send\n    response.status_code, error_message, http_response=response)\nibm_cloud_sdk_core.api_exception.ApiException: Error: Forbidden, Code: 403\n 72%|\u2588\u2588\u2588\u2588\u2588\u2588\u2588\u258f  | 3852/5347 [27:21<06:24,  3.89it/s]ERROR:root:Forbidden\nTraceback (most recent call last):\n  File \"/opt/conda/envs/Python36/lib/python3.6/site-packages/ibm_cloud_sdk_core/base_service.py\", line 229, in send\n    response.status_code, error_message, http_response=response)\nibm_cloud_sdk_core.api_exception.ApiException: Error: Forbidden, Code: 403\n 72%|\u2588\u2588\u2588\u2588\u2588\u2588\u2588\u258f  | 3853/5347 [27:21<06:11,  4.02it/s]ERROR:root:Forbidden\nTraceback (most recent call last):\n  File \"/opt/conda/envs/Python36/lib/python3.6/site-packages/ibm_cloud_sdk_core/base_service.py\", line 229, in send\n    response.status_code, error_message, http_response=response)\nibm_cloud_sdk_core.api_exception.ApiException: Error: Forbidden, Code: 403\n 72%|\u2588\u2588\u2588\u2588\u2588\u2588\u2588\u258f  | 3854/5347 [27:21<07:28,  3.33it/s]ERROR:root:Forbidden\nTraceback (most recent call last):\n  File \"/opt/conda/envs/Python36/lib/python3.6/site-packages/ibm_cloud_sdk_core/base_service.py\", line 229, in send\n    response.status_code, error_message, http_response=response)\nibm_cloud_sdk_core.api_exception.ApiException: Error: Forbidden, Code: 403\n 72%|\u2588\u2588\u2588\u2588\u2588\u2588\u2588\u258f  | 3855/5347 [27:22<08:17,  3.00it/s]ERROR:root:Forbidden\nTraceback (most recent call last):\n  File \"/opt/conda/envs/Python36/lib/python3.6/site-packages/ibm_cloud_sdk_core/base_service.py\", line 229, in send\n    response.status_code, error_message, http_response=response)\nibm_cloud_sdk_core.api_exception.ApiException: Error: Forbidden, Code: 403\n 72%|\u2588\u2588\u2588\u2588\u2588\u2588\u2588\u258f  | 3856/5347 [27:22<08:56,  2.78it/s]ERROR:root:Forbidden\nTraceback (most recent call last):\n  File \"/opt/conda/envs/Python36/lib/python3.6/site-packages/ibm_cloud_sdk_core/base_service.py\", line 229, in send\n    response.status_code, error_message, http_response=response)\nibm_cloud_sdk_core.api_exception.ApiException: Error: Forbidden, Code: 403\n 72%|\u2588\u2588\u2588\u2588\u2588\u2588\u2588\u258f  | 3857/5347 [27:23<09:34,  2.60it/s]ERROR:root:Forbidden\nTraceback (most recent call last):\n  File \"/opt/conda/envs/Python36/lib/python3.6/site-packages/ibm_cloud_sdk_core/base_service.py\", line 229, in send\n    response.status_code, error_message, http_response=response)\nibm_cloud_sdk_core.api_exception.ApiException: Error: Forbidden, Code: 403\n 72%|\u2588\u2588\u2588\u2588\u2588\u2588\u2588\u258f  | 3858/5347 [27:23<08:19,  2.98it/s]ERROR:root:Forbidden\nTraceback (most recent call last):\n  File \"/opt/conda/envs/Python36/lib/python3.6/site-packages/ibm_cloud_sdk_core/base_service.py\", line 229, in send\n    response.status_code, error_message, http_response=response)\nibm_cloud_sdk_core.api_exception.ApiException: Error: Forbidden, Code: 403\n 72%|\u2588\u2588\u2588\u2588\u2588\u2588\u2588\u258f  | 3859/5347 [27:23<08:57,  2.77it/s]ERROR:root:Forbidden\nTraceback (most recent call last):\n  File \"/opt/conda/envs/Python36/lib/python3.6/site-packages/ibm_cloud_sdk_core/base_service.py\", line 229, in send\n    response.status_code, error_message, http_response=response)\nibm_cloud_sdk_core.api_exception.ApiException: Error: Forbidden, Code: 403\n 72%|\u2588\u2588\u2588\u2588\u2588\u2588\u2588\u258f  | 3860/5347 [27:23<07:54,  3.14it/s]ERROR:root:Forbidden\nTraceback (most recent call last):\n  File \"/opt/conda/envs/Python36/lib/python3.6/site-packages/ibm_cloud_sdk_core/base_service.py\", line 229, in send\n    response.status_code, error_message, http_response=response)\nibm_cloud_sdk_core.api_exception.ApiException: Error: Forbidden, Code: 403\n", "name": "stderr"}, {"output_type": "stream", "text": " 72%|\u2588\u2588\u2588\u2588\u2588\u2588\u2588\u258f  | 3861/5347 [27:24<08:43,  2.84it/s]ERROR:root:Forbidden\nTraceback (most recent call last):\n  File \"/opt/conda/envs/Python36/lib/python3.6/site-packages/ibm_cloud_sdk_core/base_service.py\", line 229, in send\n    response.status_code, error_message, http_response=response)\nibm_cloud_sdk_core.api_exception.ApiException: Error: Forbidden, Code: 403\n 72%|\u2588\u2588\u2588\u2588\u2588\u2588\u2588\u258f  | 3862/5347 [27:24<07:40,  3.23it/s]ERROR:root:Forbidden\nTraceback (most recent call last):\n  File \"/opt/conda/envs/Python36/lib/python3.6/site-packages/ibm_cloud_sdk_core/base_service.py\", line 229, in send\n    response.status_code, error_message, http_response=response)\nibm_cloud_sdk_core.api_exception.ApiException: Error: Forbidden, Code: 403\n 72%|\u2588\u2588\u2588\u2588\u2588\u2588\u2588\u258f  | 3863/5347 [27:24<07:00,  3.53it/s]ERROR:root:Forbidden\nTraceback (most recent call last):\n  File \"/opt/conda/envs/Python36/lib/python3.6/site-packages/ibm_cloud_sdk_core/base_service.py\", line 229, in send\n    response.status_code, error_message, http_response=response)\nibm_cloud_sdk_core.api_exception.ApiException: Error: Forbidden, Code: 403\n 72%|\u2588\u2588\u2588\u2588\u2588\u2588\u2588\u258f  | 3864/5347 [27:25<07:58,  3.10it/s]ERROR:root:Forbidden\nTraceback (most recent call last):\n  File \"/opt/conda/envs/Python36/lib/python3.6/site-packages/ibm_cloud_sdk_core/base_service.py\", line 229, in send\n    response.status_code, error_message, http_response=response)\nibm_cloud_sdk_core.api_exception.ApiException: Error: Forbidden, Code: 403\n 72%|\u2588\u2588\u2588\u2588\u2588\u2588\u2588\u258f  | 3865/5347 [27:25<07:11,  3.44it/s]ERROR:root:Forbidden\nTraceback (most recent call last):\n  File \"/opt/conda/envs/Python36/lib/python3.6/site-packages/ibm_cloud_sdk_core/base_service.py\", line 229, in send\n    response.status_code, error_message, http_response=response)\nibm_cloud_sdk_core.api_exception.ApiException: Error: Forbidden, Code: 403\n 72%|\u2588\u2588\u2588\u2588\u2588\u2588\u2588\u258f  | 3866/5347 [27:25<06:23,  3.86it/s]ERROR:root:Forbidden\nTraceback (most recent call last):\n  File \"/opt/conda/envs/Python36/lib/python3.6/site-packages/ibm_cloud_sdk_core/base_service.py\", line 229, in send\n    response.status_code, error_message, http_response=response)\nibm_cloud_sdk_core.api_exception.ApiException: Error: Forbidden, Code: 403\n 72%|\u2588\u2588\u2588\u2588\u2588\u2588\u2588\u258f  | 3867/5347 [27:25<07:29,  3.29it/s]ERROR:root:Forbidden\nTraceback (most recent call last):\n  File \"/opt/conda/envs/Python36/lib/python3.6/site-packages/ibm_cloud_sdk_core/base_service.py\", line 229, in send\n    response.status_code, error_message, http_response=response)\nibm_cloud_sdk_core.api_exception.ApiException: Error: Forbidden, Code: 403\n 72%|\u2588\u2588\u2588\u2588\u2588\u2588\u2588\u258f  | 3868/5347 [27:26<06:54,  3.57it/s]ERROR:root:Forbidden\nTraceback (most recent call last):\n  File \"/opt/conda/envs/Python36/lib/python3.6/site-packages/ibm_cloud_sdk_core/base_service.py\", line 229, in send\n    response.status_code, error_message, http_response=response)\nibm_cloud_sdk_core.api_exception.ApiException: Error: Forbidden, Code: 403\n 72%|\u2588\u2588\u2588\u2588\u2588\u2588\u2588\u258f  | 3869/5347 [27:26<07:53,  3.12it/s]ERROR:root:Forbidden\nTraceback (most recent call last):\n  File \"/opt/conda/envs/Python36/lib/python3.6/site-packages/ibm_cloud_sdk_core/base_service.py\", line 229, in send\n    response.status_code, error_message, http_response=response)\nibm_cloud_sdk_core.api_exception.ApiException: Error: Forbidden, Code: 403\n 72%|\u2588\u2588\u2588\u2588\u2588\u2588\u2588\u258f  | 3870/5347 [27:27<08:39,  2.84it/s]ERROR:root:Forbidden\nTraceback (most recent call last):\n  File \"/opt/conda/envs/Python36/lib/python3.6/site-packages/ibm_cloud_sdk_core/base_service.py\", line 229, in send\n    response.status_code, error_message, http_response=response)\nibm_cloud_sdk_core.api_exception.ApiException: Error: Forbidden, Code: 403\n 72%|\u2588\u2588\u2588\u2588\u2588\u2588\u2588\u258f  | 3871/5347 [27:27<09:08,  2.69it/s]ERROR:root:Forbidden\nTraceback (most recent call last):\n  File \"/opt/conda/envs/Python36/lib/python3.6/site-packages/ibm_cloud_sdk_core/base_service.py\", line 229, in send\n    response.status_code, error_message, http_response=response)\nibm_cloud_sdk_core.api_exception.ApiException: Error: Forbidden, Code: 403\n 72%|\u2588\u2588\u2588\u2588\u2588\u2588\u2588\u258f  | 3872/5347 [27:27<09:23,  2.62it/s]ERROR:root:Forbidden\nTraceback (most recent call last):\n  File \"/opt/conda/envs/Python36/lib/python3.6/site-packages/ibm_cloud_sdk_core/base_service.py\", line 229, in send\n    response.status_code, error_message, http_response=response)\nibm_cloud_sdk_core.api_exception.ApiException: Error: Forbidden, Code: 403\n 72%|\u2588\u2588\u2588\u2588\u2588\u2588\u2588\u258f  | 3873/5347 [27:28<09:42,  2.53it/s]ERROR:root:Forbidden\nTraceback (most recent call last):\n  File \"/opt/conda/envs/Python36/lib/python3.6/site-packages/ibm_cloud_sdk_core/base_service.py\", line 229, in send\n    response.status_code, error_message, http_response=response)\nibm_cloud_sdk_core.api_exception.ApiException: Error: Forbidden, Code: 403\n 72%|\u2588\u2588\u2588\u2588\u2588\u2588\u2588\u258f  | 3874/5347 [27:28<09:59,  2.46it/s]ERROR:root:Forbidden\nTraceback (most recent call last):\n  File \"/opt/conda/envs/Python36/lib/python3.6/site-packages/ibm_cloud_sdk_core/base_service.py\", line 229, in send\n    response.status_code, error_message, http_response=response)\nibm_cloud_sdk_core.api_exception.ApiException: Error: Forbidden, Code: 403\n 72%|\u2588\u2588\u2588\u2588\u2588\u2588\u2588\u258f  | 3875/5347 [27:28<08:17,  2.96it/s]ERROR:root:Forbidden\nTraceback (most recent call last):\n  File \"/opt/conda/envs/Python36/lib/python3.6/site-packages/ibm_cloud_sdk_core/base_service.py\", line 229, in send\n    response.status_code, error_message, http_response=response)\nibm_cloud_sdk_core.api_exception.ApiException: Error: Forbidden, Code: 403\n 72%|\u2588\u2588\u2588\u2588\u2588\u2588\u2588\u258f  | 3876/5347 [27:29<07:13,  3.39it/s]ERROR:root:Forbidden\nTraceback (most recent call last):\n  File \"/opt/conda/envs/Python36/lib/python3.6/site-packages/ibm_cloud_sdk_core/base_service.py\", line 229, in send\n    response.status_code, error_message, http_response=response)\nibm_cloud_sdk_core.api_exception.ApiException: Error: Forbidden, Code: 403\n 73%|\u2588\u2588\u2588\u2588\u2588\u2588\u2588\u258e  | 3877/5347 [27:29<08:26,  2.90it/s]ERROR:root:Forbidden\nTraceback (most recent call last):\n  File \"/opt/conda/envs/Python36/lib/python3.6/site-packages/ibm_cloud_sdk_core/base_service.py\", line 229, in send\n    response.status_code, error_message, http_response=response)\nibm_cloud_sdk_core.api_exception.ApiException: Error: Forbidden, Code: 403\n 73%|\u2588\u2588\u2588\u2588\u2588\u2588\u2588\u258e  | 3878/5347 [27:30<09:05,  2.69it/s]ERROR:root:Forbidden\nTraceback (most recent call last):\n  File \"/opt/conda/envs/Python36/lib/python3.6/site-packages/ibm_cloud_sdk_core/base_service.py\", line 229, in send\n    response.status_code, error_message, http_response=response)\nibm_cloud_sdk_core.api_exception.ApiException: Error: Forbidden, Code: 403\n 73%|\u2588\u2588\u2588\u2588\u2588\u2588\u2588\u258e  | 3879/5347 [27:30<09:25,  2.60it/s]ERROR:root:Forbidden\nTraceback (most recent call last):\n  File \"/opt/conda/envs/Python36/lib/python3.6/site-packages/ibm_cloud_sdk_core/base_service.py\", line 229, in send\n    response.status_code, error_message, http_response=response)\nibm_cloud_sdk_core.api_exception.ApiException: Error: Forbidden, Code: 403\n 73%|\u2588\u2588\u2588\u2588\u2588\u2588\u2588\u258e  | 3880/5347 [27:30<07:53,  3.10it/s]ERROR:root:Forbidden\nTraceback (most recent call last):\n  File \"/opt/conda/envs/Python36/lib/python3.6/site-packages/ibm_cloud_sdk_core/base_service.py\", line 229, in send\n    response.status_code, error_message, http_response=response)\nibm_cloud_sdk_core.api_exception.ApiException: Error: Forbidden, Code: 403\n 73%|\u2588\u2588\u2588\u2588\u2588\u2588\u2588\u258e  | 3881/5347 [27:31<08:38,  2.83it/s]ERROR:root:Forbidden\nTraceback (most recent call last):\n  File \"/opt/conda/envs/Python36/lib/python3.6/site-packages/ibm_cloud_sdk_core/base_service.py\", line 229, in send\n    response.status_code, error_message, http_response=response)\nibm_cloud_sdk_core.api_exception.ApiException: Error: Forbidden, Code: 403\n 73%|\u2588\u2588\u2588\u2588\u2588\u2588\u2588\u258e  | 3882/5347 [27:31<07:41,  3.17it/s]ERROR:root:Forbidden\nTraceback (most recent call last):\n  File \"/opt/conda/envs/Python36/lib/python3.6/site-packages/ibm_cloud_sdk_core/base_service.py\", line 229, in send\n    response.status_code, error_message, http_response=response)\nibm_cloud_sdk_core.api_exception.ApiException: Error: Forbidden, Code: 403\n 73%|\u2588\u2588\u2588\u2588\u2588\u2588\u2588\u258e  | 3883/5347 [27:31<06:58,  3.50it/s]ERROR:root:Forbidden\nTraceback (most recent call last):\n  File \"/opt/conda/envs/Python36/lib/python3.6/site-packages/ibm_cloud_sdk_core/base_service.py\", line 229, in send\n    response.status_code, error_message, http_response=response)\nibm_cloud_sdk_core.api_exception.ApiException: Error: Forbidden, Code: 403\n", "name": "stderr"}, {"output_type": "stream", "text": " 73%|\u2588\u2588\u2588\u2588\u2588\u2588\u2588\u258e  | 3884/5347 [27:31<06:44,  3.62it/s]ERROR:root:Forbidden\nTraceback (most recent call last):\n  File \"/opt/conda/envs/Python36/lib/python3.6/site-packages/ibm_cloud_sdk_core/base_service.py\", line 229, in send\n    response.status_code, error_message, http_response=response)\nibm_cloud_sdk_core.api_exception.ApiException: Error: Forbidden, Code: 403\n 73%|\u2588\u2588\u2588\u2588\u2588\u2588\u2588\u258e  | 3885/5347 [27:31<06:32,  3.72it/s]ERROR:root:Forbidden\nTraceback (most recent call last):\n  File \"/opt/conda/envs/Python36/lib/python3.6/site-packages/ibm_cloud_sdk_core/base_service.py\", line 229, in send\n    response.status_code, error_message, http_response=response)\nibm_cloud_sdk_core.api_exception.ApiException: Error: Forbidden, Code: 403\n 73%|\u2588\u2588\u2588\u2588\u2588\u2588\u2588\u258e  | 3886/5347 [27:32<06:28,  3.76it/s]ERROR:root:Forbidden\nTraceback (most recent call last):\n  File \"/opt/conda/envs/Python36/lib/python3.6/site-packages/ibm_cloud_sdk_core/base_service.py\", line 229, in send\n    response.status_code, error_message, http_response=response)\nibm_cloud_sdk_core.api_exception.ApiException: Error: Forbidden, Code: 403\n 73%|\u2588\u2588\u2588\u2588\u2588\u2588\u2588\u258e  | 3887/5347 [27:32<05:55,  4.10it/s]ERROR:root:Forbidden\nTraceback (most recent call last):\n  File \"/opt/conda/envs/Python36/lib/python3.6/site-packages/ibm_cloud_sdk_core/base_service.py\", line 229, in send\n    response.status_code, error_message, http_response=response)\nibm_cloud_sdk_core.api_exception.ApiException: Error: Forbidden, Code: 403\n 73%|\u2588\u2588\u2588\u2588\u2588\u2588\u2588\u258e  | 3888/5347 [27:32<05:47,  4.20it/s]ERROR:root:Forbidden\nTraceback (most recent call last):\n  File \"/opt/conda/envs/Python36/lib/python3.6/site-packages/ibm_cloud_sdk_core/base_service.py\", line 229, in send\n    response.status_code, error_message, http_response=response)\nibm_cloud_sdk_core.api_exception.ApiException: Error: Forbidden, Code: 403\n 73%|\u2588\u2588\u2588\u2588\u2588\u2588\u2588\u258e  | 3889/5347 [27:32<05:35,  4.35it/s]ERROR:root:Forbidden\nTraceback (most recent call last):\n  File \"/opt/conda/envs/Python36/lib/python3.6/site-packages/ibm_cloud_sdk_core/base_service.py\", line 229, in send\n    response.status_code, error_message, http_response=response)\nibm_cloud_sdk_core.api_exception.ApiException: Error: Forbidden, Code: 403\n 73%|\u2588\u2588\u2588\u2588\u2588\u2588\u2588\u258e  | 3890/5347 [27:33<07:02,  3.44it/s]ERROR:root:Forbidden\nTraceback (most recent call last):\n  File \"/opt/conda/envs/Python36/lib/python3.6/site-packages/ibm_cloud_sdk_core/base_service.py\", line 229, in send\n    response.status_code, error_message, http_response=response)\nibm_cloud_sdk_core.api_exception.ApiException: Error: Forbidden, Code: 403\n 73%|\u2588\u2588\u2588\u2588\u2588\u2588\u2588\u258e  | 3891/5347 [27:33<06:26,  3.77it/s]ERROR:root:Forbidden\nTraceback (most recent call last):\n  File \"/opt/conda/envs/Python36/lib/python3.6/site-packages/ibm_cloud_sdk_core/base_service.py\", line 229, in send\n    response.status_code, error_message, http_response=response)\nibm_cloud_sdk_core.api_exception.ApiException: Error: Forbidden, Code: 403\n 73%|\u2588\u2588\u2588\u2588\u2588\u2588\u2588\u258e  | 3892/5347 [27:33<07:32,  3.22it/s]ERROR:root:Forbidden\nTraceback (most recent call last):\n  File \"/opt/conda/envs/Python36/lib/python3.6/site-packages/ibm_cloud_sdk_core/base_service.py\", line 229, in send\n    response.status_code, error_message, http_response=response)\nibm_cloud_sdk_core.api_exception.ApiException: Error: Forbidden, Code: 403\n 73%|\u2588\u2588\u2588\u2588\u2588\u2588\u2588\u258e  | 3893/5347 [27:34<06:44,  3.59it/s]ERROR:root:Forbidden\nTraceback (most recent call last):\n  File \"/opt/conda/envs/Python36/lib/python3.6/site-packages/ibm_cloud_sdk_core/base_service.py\", line 229, in send\n    response.status_code, error_message, http_response=response)\nibm_cloud_sdk_core.api_exception.ApiException: Error: Forbidden, Code: 403\n 73%|\u2588\u2588\u2588\u2588\u2588\u2588\u2588\u258e  | 3894/5347 [27:34<07:49,  3.10it/s]ERROR:root:Forbidden\nTraceback (most recent call last):\n  File \"/opt/conda/envs/Python36/lib/python3.6/site-packages/ibm_cloud_sdk_core/base_service.py\", line 229, in send\n    response.status_code, error_message, http_response=response)\nibm_cloud_sdk_core.api_exception.ApiException: Error: Forbidden, Code: 403\n 73%|\u2588\u2588\u2588\u2588\u2588\u2588\u2588\u258e  | 3895/5347 [27:34<07:13,  3.35it/s]ERROR:root:Forbidden\nTraceback (most recent call last):\n  File \"/opt/conda/envs/Python36/lib/python3.6/site-packages/ibm_cloud_sdk_core/base_service.py\", line 229, in send\n    response.status_code, error_message, http_response=response)\nibm_cloud_sdk_core.api_exception.ApiException: Error: Forbidden, Code: 403\n 73%|\u2588\u2588\u2588\u2588\u2588\u2588\u2588\u258e  | 3896/5347 [27:35<06:39,  3.64it/s]ERROR:root:Forbidden\nTraceback (most recent call last):\n  File \"/opt/conda/envs/Python36/lib/python3.6/site-packages/ibm_cloud_sdk_core/base_service.py\", line 229, in send\n    response.status_code, error_message, http_response=response)\nibm_cloud_sdk_core.api_exception.ApiException: Error: Forbidden, Code: 403\n 73%|\u2588\u2588\u2588\u2588\u2588\u2588\u2588\u258e  | 3897/5347 [27:35<06:11,  3.90it/s]ERROR:root:Forbidden\nTraceback (most recent call last):\n  File \"/opt/conda/envs/Python36/lib/python3.6/site-packages/ibm_cloud_sdk_core/base_service.py\", line 229, in send\n    response.status_code, error_message, http_response=response)\nibm_cloud_sdk_core.api_exception.ApiException: Error: Forbidden, Code: 403\n 73%|\u2588\u2588\u2588\u2588\u2588\u2588\u2588\u258e  | 3898/5347 [27:35<06:08,  3.93it/s]ERROR:root:Forbidden\nTraceback (most recent call last):\n  File \"/opt/conda/envs/Python36/lib/python3.6/site-packages/ibm_cloud_sdk_core/base_service.py\", line 229, in send\n    response.status_code, error_message, http_response=response)\nibm_cloud_sdk_core.api_exception.ApiException: Error: Forbidden, Code: 403\n 73%|\u2588\u2588\u2588\u2588\u2588\u2588\u2588\u258e  | 3899/5347 [27:35<05:47,  4.17it/s]ERROR:root:Forbidden\nTraceback (most recent call last):\n  File \"/opt/conda/envs/Python36/lib/python3.6/site-packages/ibm_cloud_sdk_core/base_service.py\", line 229, in send\n    response.status_code, error_message, http_response=response)\nibm_cloud_sdk_core.api_exception.ApiException: Error: Forbidden, Code: 403\n 73%|\u2588\u2588\u2588\u2588\u2588\u2588\u2588\u258e  | 3900/5347 [27:35<05:37,  4.29it/s]ERROR:root:Forbidden\nTraceback (most recent call last):\n  File \"/opt/conda/envs/Python36/lib/python3.6/site-packages/ibm_cloud_sdk_core/base_service.py\", line 229, in send\n    response.status_code, error_message, http_response=response)\nibm_cloud_sdk_core.api_exception.ApiException: Error: Forbidden, Code: 403\n 73%|\u2588\u2588\u2588\u2588\u2588\u2588\u2588\u258e  | 3901/5347 [27:36<05:29,  4.39it/s]ERROR:root:Forbidden\nTraceback (most recent call last):\n  File \"/opt/conda/envs/Python36/lib/python3.6/site-packages/ibm_cloud_sdk_core/base_service.py\", line 229, in send\n    response.status_code, error_message, http_response=response)\nibm_cloud_sdk_core.api_exception.ApiException: Error: Forbidden, Code: 403\n 73%|\u2588\u2588\u2588\u2588\u2588\u2588\u2588\u258e  | 3902/5347 [27:36<05:23,  4.46it/s]ERROR:root:Forbidden\nTraceback (most recent call last):\n  File \"/opt/conda/envs/Python36/lib/python3.6/site-packages/ibm_cloud_sdk_core/base_service.py\", line 229, in send\n    response.status_code, error_message, http_response=response)\nibm_cloud_sdk_core.api_exception.ApiException: Error: Forbidden, Code: 403\n 73%|\u2588\u2588\u2588\u2588\u2588\u2588\u2588\u258e  | 3903/5347 [27:36<05:27,  4.41it/s]ERROR:root:Forbidden\nTraceback (most recent call last):\n  File \"/opt/conda/envs/Python36/lib/python3.6/site-packages/ibm_cloud_sdk_core/base_service.py\", line 229, in send\n    response.status_code, error_message, http_response=response)\nibm_cloud_sdk_core.api_exception.ApiException: Error: Forbidden, Code: 403\n 73%|\u2588\u2588\u2588\u2588\u2588\u2588\u2588\u258e  | 3904/5347 [27:36<05:30,  4.37it/s]ERROR:root:Forbidden\nTraceback (most recent call last):\n  File \"/opt/conda/envs/Python36/lib/python3.6/site-packages/ibm_cloud_sdk_core/base_service.py\", line 229, in send\n    response.status_code, error_message, http_response=response)\nibm_cloud_sdk_core.api_exception.ApiException: Error: Forbidden, Code: 403\n 73%|\u2588\u2588\u2588\u2588\u2588\u2588\u2588\u258e  | 3905/5347 [27:36<05:08,  4.67it/s]ERROR:root:Forbidden\nTraceback (most recent call last):\n  File \"/opt/conda/envs/Python36/lib/python3.6/site-packages/ibm_cloud_sdk_core/base_service.py\", line 229, in send\n    response.status_code, error_message, http_response=response)\nibm_cloud_sdk_core.api_exception.ApiException: Error: Forbidden, Code: 403\n 73%|\u2588\u2588\u2588\u2588\u2588\u2588\u2588\u258e  | 3906/5347 [27:37<06:35,  3.65it/s]ERROR:root:Forbidden\nTraceback (most recent call last):\n  File \"/opt/conda/envs/Python36/lib/python3.6/site-packages/ibm_cloud_sdk_core/base_service.py\", line 229, in send\n    response.status_code, error_message, http_response=response)\nibm_cloud_sdk_core.api_exception.ApiException: Error: Forbidden, Code: 403\n", "name": "stderr"}, {"output_type": "stream", "text": " 73%|\u2588\u2588\u2588\u2588\u2588\u2588\u2588\u258e  | 3907/5347 [27:37<06:23,  3.75it/s]ERROR:root:Forbidden\nTraceback (most recent call last):\n  File \"/opt/conda/envs/Python36/lib/python3.6/site-packages/ibm_cloud_sdk_core/base_service.py\", line 229, in send\n    response.status_code, error_message, http_response=response)\nibm_cloud_sdk_core.api_exception.ApiException: Error: Forbidden, Code: 403\n 73%|\u2588\u2588\u2588\u2588\u2588\u2588\u2588\u258e  | 3908/5347 [27:37<05:45,  4.16it/s]ERROR:root:Forbidden\nTraceback (most recent call last):\n  File \"/opt/conda/envs/Python36/lib/python3.6/site-packages/ibm_cloud_sdk_core/base_service.py\", line 229, in send\n    response.status_code, error_message, http_response=response)\nibm_cloud_sdk_core.api_exception.ApiException: Error: Forbidden, Code: 403\n 73%|\u2588\u2588\u2588\u2588\u2588\u2588\u2588\u258e  | 3909/5347 [27:38<05:34,  4.29it/s]ERROR:root:Forbidden\nTraceback (most recent call last):\n  File \"/opt/conda/envs/Python36/lib/python3.6/site-packages/ibm_cloud_sdk_core/base_service.py\", line 229, in send\n    response.status_code, error_message, http_response=response)\nibm_cloud_sdk_core.api_exception.ApiException: Error: Forbidden, Code: 403\n 73%|\u2588\u2588\u2588\u2588\u2588\u2588\u2588\u258e  | 3910/5347 [27:38<05:11,  4.61it/s]ERROR:root:Forbidden\nTraceback (most recent call last):\n  File \"/opt/conda/envs/Python36/lib/python3.6/site-packages/ibm_cloud_sdk_core/base_service.py\", line 229, in send\n    response.status_code, error_message, http_response=response)\nibm_cloud_sdk_core.api_exception.ApiException: Error: Forbidden, Code: 403\n 73%|\u2588\u2588\u2588\u2588\u2588\u2588\u2588\u258e  | 3911/5347 [27:38<05:18,  4.52it/s]ERROR:root:Forbidden\nTraceback (most recent call last):\n  File \"/opt/conda/envs/Python36/lib/python3.6/site-packages/ibm_cloud_sdk_core/base_service.py\", line 229, in send\n    response.status_code, error_message, http_response=response)\nibm_cloud_sdk_core.api_exception.ApiException: Error: Forbidden, Code: 403\n 73%|\u2588\u2588\u2588\u2588\u2588\u2588\u2588\u258e  | 3912/5347 [27:38<05:10,  4.63it/s]ERROR:root:Forbidden\nTraceback (most recent call last):\n  File \"/opt/conda/envs/Python36/lib/python3.6/site-packages/ibm_cloud_sdk_core/base_service.py\", line 229, in send\n    response.status_code, error_message, http_response=response)\nibm_cloud_sdk_core.api_exception.ApiException: Error: Forbidden, Code: 403\n 73%|\u2588\u2588\u2588\u2588\u2588\u2588\u2588\u258e  | 3913/5347 [27:38<05:17,  4.52it/s]ERROR:root:Forbidden\nTraceback (most recent call last):\n  File \"/opt/conda/envs/Python36/lib/python3.6/site-packages/ibm_cloud_sdk_core/base_service.py\", line 229, in send\n    response.status_code, error_message, http_response=response)\nibm_cloud_sdk_core.api_exception.ApiException: Error: Forbidden, Code: 403\n 73%|\u2588\u2588\u2588\u2588\u2588\u2588\u2588\u258e  | 3914/5347 [27:39<05:23,  4.43it/s]ERROR:root:Forbidden\nTraceback (most recent call last):\n  File \"/opt/conda/envs/Python36/lib/python3.6/site-packages/ibm_cloud_sdk_core/base_service.py\", line 229, in send\n    response.status_code, error_message, http_response=response)\nibm_cloud_sdk_core.api_exception.ApiException: Error: Forbidden, Code: 403\n 73%|\u2588\u2588\u2588\u2588\u2588\u2588\u2588\u258e  | 3915/5347 [27:39<05:14,  4.55it/s]ERROR:root:Forbidden\nTraceback (most recent call last):\n  File \"/opt/conda/envs/Python36/lib/python3.6/site-packages/ibm_cloud_sdk_core/base_service.py\", line 229, in send\n    response.status_code, error_message, http_response=response)\nibm_cloud_sdk_core.api_exception.ApiException: Error: Forbidden, Code: 403\n 73%|\u2588\u2588\u2588\u2588\u2588\u2588\u2588\u258e  | 3916/5347 [27:39<05:22,  4.43it/s]ERROR:root:Forbidden\nTraceback (most recent call last):\n  File \"/opt/conda/envs/Python36/lib/python3.6/site-packages/ibm_cloud_sdk_core/base_service.py\", line 229, in send\n    response.status_code, error_message, http_response=response)\nibm_cloud_sdk_core.api_exception.ApiException: Error: Forbidden, Code: 403\n 73%|\u2588\u2588\u2588\u2588\u2588\u2588\u2588\u258e  | 3917/5347 [27:39<05:14,  4.55it/s]ERROR:root:Forbidden\nTraceback (most recent call last):\n  File \"/opt/conda/envs/Python36/lib/python3.6/site-packages/ibm_cloud_sdk_core/base_service.py\", line 229, in send\n    response.status_code, error_message, http_response=response)\nibm_cloud_sdk_core.api_exception.ApiException: Error: Forbidden, Code: 403\n 73%|\u2588\u2588\u2588\u2588\u2588\u2588\u2588\u258e  | 3918/5347 [27:39<05:14,  4.54it/s]ERROR:root:Forbidden\nTraceback (most recent call last):\n  File \"/opt/conda/envs/Python36/lib/python3.6/site-packages/ibm_cloud_sdk_core/base_service.py\", line 229, in send\n    response.status_code, error_message, http_response=response)\nibm_cloud_sdk_core.api_exception.ApiException: Error: Forbidden, Code: 403\n 73%|\u2588\u2588\u2588\u2588\u2588\u2588\u2588\u258e  | 3919/5347 [27:40<05:16,  4.51it/s]ERROR:root:Forbidden\nTraceback (most recent call last):\n  File \"/opt/conda/envs/Python36/lib/python3.6/site-packages/ibm_cloud_sdk_core/base_service.py\", line 229, in send\n    response.status_code, error_message, http_response=response)\nibm_cloud_sdk_core.api_exception.ApiException: Error: Forbidden, Code: 403\n 73%|\u2588\u2588\u2588\u2588\u2588\u2588\u2588\u258e  | 3920/5347 [27:40<05:05,  4.67it/s]ERROR:root:Forbidden\nTraceback (most recent call last):\n  File \"/opt/conda/envs/Python36/lib/python3.6/site-packages/ibm_cloud_sdk_core/base_service.py\", line 229, in send\n    response.status_code, error_message, http_response=response)\nibm_cloud_sdk_core.api_exception.ApiException: Error: Forbidden, Code: 403\n 73%|\u2588\u2588\u2588\u2588\u2588\u2588\u2588\u258e  | 3921/5347 [27:40<06:31,  3.64it/s]ERROR:root:Forbidden\nTraceback (most recent call last):\n  File \"/opt/conda/envs/Python36/lib/python3.6/site-packages/ibm_cloud_sdk_core/base_service.py\", line 229, in send\n    response.status_code, error_message, http_response=response)\nibm_cloud_sdk_core.api_exception.ApiException: Error: Forbidden, Code: 403\n 73%|\u2588\u2588\u2588\u2588\u2588\u2588\u2588\u258e  | 3922/5347 [27:41<06:07,  3.88it/s]ERROR:root:Forbidden\nTraceback (most recent call last):\n  File \"/opt/conda/envs/Python36/lib/python3.6/site-packages/ibm_cloud_sdk_core/base_service.py\", line 229, in send\n    response.status_code, error_message, http_response=response)\nibm_cloud_sdk_core.api_exception.ApiException: Error: Forbidden, Code: 403\n 73%|\u2588\u2588\u2588\u2588\u2588\u2588\u2588\u258e  | 3923/5347 [27:41<07:10,  3.31it/s]ERROR:root:Forbidden\nTraceback (most recent call last):\n  File \"/opt/conda/envs/Python36/lib/python3.6/site-packages/ibm_cloud_sdk_core/base_service.py\", line 229, in send\n    response.status_code, error_message, http_response=response)\nibm_cloud_sdk_core.api_exception.ApiException: Error: Forbidden, Code: 403\n 73%|\u2588\u2588\u2588\u2588\u2588\u2588\u2588\u258e  | 3924/5347 [27:41<06:36,  3.58it/s]ERROR:root:Forbidden\nTraceback (most recent call last):\n  File \"/opt/conda/envs/Python36/lib/python3.6/site-packages/ibm_cloud_sdk_core/base_service.py\", line 229, in send\n    response.status_code, error_message, http_response=response)\nibm_cloud_sdk_core.api_exception.ApiException: Error: Forbidden, Code: 403\n 73%|\u2588\u2588\u2588\u2588\u2588\u2588\u2588\u258e  | 3925/5347 [27:41<06:09,  3.85it/s]ERROR:root:Forbidden\nTraceback (most recent call last):\n  File \"/opt/conda/envs/Python36/lib/python3.6/site-packages/ibm_cloud_sdk_core/base_service.py\", line 229, in send\n    response.status_code, error_message, http_response=response)\nibm_cloud_sdk_core.api_exception.ApiException: Error: Forbidden, Code: 403\n 73%|\u2588\u2588\u2588\u2588\u2588\u2588\u2588\u258e  | 3926/5347 [27:42<05:47,  4.09it/s]ERROR:root:Forbidden\nTraceback (most recent call last):\n  File \"/opt/conda/envs/Python36/lib/python3.6/site-packages/ibm_cloud_sdk_core/base_service.py\", line 229, in send\n    response.status_code, error_message, http_response=response)\nibm_cloud_sdk_core.api_exception.ApiException: Error: Forbidden, Code: 403\n 73%|\u2588\u2588\u2588\u2588\u2588\u2588\u2588\u258e  | 3927/5347 [27:42<05:31,  4.28it/s]ERROR:root:Forbidden\nTraceback (most recent call last):\n  File \"/opt/conda/envs/Python36/lib/python3.6/site-packages/ibm_cloud_sdk_core/base_service.py\", line 229, in send\n    response.status_code, error_message, http_response=response)\nibm_cloud_sdk_core.api_exception.ApiException: Error: Forbidden, Code: 403\n 73%|\u2588\u2588\u2588\u2588\u2588\u2588\u2588\u258e  | 3928/5347 [27:42<05:34,  4.25it/s]ERROR:root:Forbidden\nTraceback (most recent call last):\n  File \"/opt/conda/envs/Python36/lib/python3.6/site-packages/ibm_cloud_sdk_core/base_service.py\", line 229, in send\n    response.status_code, error_message, http_response=response)\nibm_cloud_sdk_core.api_exception.ApiException: Error: Forbidden, Code: 403\n 73%|\u2588\u2588\u2588\u2588\u2588\u2588\u2588\u258e  | 3929/5347 [27:42<05:11,  4.55it/s]ERROR:root:Forbidden\nTraceback (most recent call last):\n  File \"/opt/conda/envs/Python36/lib/python3.6/site-packages/ibm_cloud_sdk_core/base_service.py\", line 229, in send\n    response.status_code, error_message, http_response=response)\nibm_cloud_sdk_core.api_exception.ApiException: Error: Forbidden, Code: 403\n", "name": "stderr"}, {"output_type": "stream", "text": " 73%|\u2588\u2588\u2588\u2588\u2588\u2588\u2588\u258e  | 3930/5347 [27:42<05:10,  4.56it/s]ERROR:root:Forbidden\nTraceback (most recent call last):\n  File \"/opt/conda/envs/Python36/lib/python3.6/site-packages/ibm_cloud_sdk_core/base_service.py\", line 229, in send\n    response.status_code, error_message, http_response=response)\nibm_cloud_sdk_core.api_exception.ApiException: Error: Forbidden, Code: 403\n 74%|\u2588\u2588\u2588\u2588\u2588\u2588\u2588\u258e  | 3931/5347 [27:43<05:12,  4.54it/s]ERROR:root:Forbidden\nTraceback (most recent call last):\n  File \"/opt/conda/envs/Python36/lib/python3.6/site-packages/ibm_cloud_sdk_core/base_service.py\", line 229, in send\n    response.status_code, error_message, http_response=response)\nibm_cloud_sdk_core.api_exception.ApiException: Error: Forbidden, Code: 403\n 74%|\u2588\u2588\u2588\u2588\u2588\u2588\u2588\u258e  | 3932/5347 [27:43<05:13,  4.52it/s]ERROR:root:Forbidden\nTraceback (most recent call last):\n  File \"/opt/conda/envs/Python36/lib/python3.6/site-packages/ibm_cloud_sdk_core/base_service.py\", line 229, in send\n    response.status_code, error_message, http_response=response)\nibm_cloud_sdk_core.api_exception.ApiException: Error: Forbidden, Code: 403\n 74%|\u2588\u2588\u2588\u2588\u2588\u2588\u2588\u258e  | 3933/5347 [27:43<04:52,  4.83it/s]ERROR:root:Forbidden\nTraceback (most recent call last):\n  File \"/opt/conda/envs/Python36/lib/python3.6/site-packages/ibm_cloud_sdk_core/base_service.py\", line 229, in send\n    response.status_code, error_message, http_response=response)\nibm_cloud_sdk_core.api_exception.ApiException: Error: Forbidden, Code: 403\n 74%|\u2588\u2588\u2588\u2588\u2588\u2588\u2588\u258e  | 3934/5347 [27:43<04:48,  4.90it/s]ERROR:root:Forbidden\nTraceback (most recent call last):\n  File \"/opt/conda/envs/Python36/lib/python3.6/site-packages/ibm_cloud_sdk_core/base_service.py\", line 229, in send\n    response.status_code, error_message, http_response=response)\nibm_cloud_sdk_core.api_exception.ApiException: Error: Forbidden, Code: 403\n 74%|\u2588\u2588\u2588\u2588\u2588\u2588\u2588\u258e  | 3935/5347 [27:43<04:40,  5.04it/s]ERROR:root:Forbidden\nTraceback (most recent call last):\n  File \"/opt/conda/envs/Python36/lib/python3.6/site-packages/ibm_cloud_sdk_core/base_service.py\", line 229, in send\n    response.status_code, error_message, http_response=response)\nibm_cloud_sdk_core.api_exception.ApiException: Error: Forbidden, Code: 403\n 74%|\u2588\u2588\u2588\u2588\u2588\u2588\u2588\u258e  | 3936/5347 [27:44<04:45,  4.94it/s]ERROR:root:Forbidden\nTraceback (most recent call last):\n  File \"/opt/conda/envs/Python36/lib/python3.6/site-packages/ibm_cloud_sdk_core/base_service.py\", line 229, in send\n    response.status_code, error_message, http_response=response)\nibm_cloud_sdk_core.api_exception.ApiException: Error: Forbidden, Code: 403\n 74%|\u2588\u2588\u2588\u2588\u2588\u2588\u2588\u258e  | 3937/5347 [27:44<04:36,  5.10it/s]ERROR:root:Forbidden\nTraceback (most recent call last):\n  File \"/opt/conda/envs/Python36/lib/python3.6/site-packages/ibm_cloud_sdk_core/base_service.py\", line 229, in send\n    response.status_code, error_message, http_response=response)\nibm_cloud_sdk_core.api_exception.ApiException: Error: Forbidden, Code: 403\n 74%|\u2588\u2588\u2588\u2588\u2588\u2588\u2588\u258e  | 3938/5347 [27:44<04:49,  4.87it/s]ERROR:root:Forbidden\nTraceback (most recent call last):\n  File \"/opt/conda/envs/Python36/lib/python3.6/site-packages/ibm_cloud_sdk_core/base_service.py\", line 229, in send\n    response.status_code, error_message, http_response=response)\nibm_cloud_sdk_core.api_exception.ApiException: Error: Forbidden, Code: 403\n 74%|\u2588\u2588\u2588\u2588\u2588\u2588\u2588\u258e  | 3939/5347 [27:44<04:49,  4.86it/s]ERROR:root:Forbidden\nTraceback (most recent call last):\n  File \"/opt/conda/envs/Python36/lib/python3.6/site-packages/ibm_cloud_sdk_core/base_service.py\", line 229, in send\n    response.status_code, error_message, http_response=response)\nibm_cloud_sdk_core.api_exception.ApiException: Error: Forbidden, Code: 403\n 74%|\u2588\u2588\u2588\u2588\u2588\u2588\u2588\u258e  | 3940/5347 [27:45<05:00,  4.69it/s]ERROR:root:Forbidden\nTraceback (most recent call last):\n  File \"/opt/conda/envs/Python36/lib/python3.6/site-packages/ibm_cloud_sdk_core/base_service.py\", line 229, in send\n    response.status_code, error_message, http_response=response)\nibm_cloud_sdk_core.api_exception.ApiException: Error: Forbidden, Code: 403\n 74%|\u2588\u2588\u2588\u2588\u2588\u2588\u2588\u258e  | 3941/5347 [27:45<05:10,  4.54it/s]ERROR:root:Forbidden\nTraceback (most recent call last):\n  File \"/opt/conda/envs/Python36/lib/python3.6/site-packages/ibm_cloud_sdk_core/base_service.py\", line 229, in send\n    response.status_code, error_message, http_response=response)\nibm_cloud_sdk_core.api_exception.ApiException: Error: Forbidden, Code: 403\n 74%|\u2588\u2588\u2588\u2588\u2588\u2588\u2588\u258e  | 3942/5347 [27:45<05:11,  4.52it/s]ERROR:root:Forbidden\nTraceback (most recent call last):\n  File \"/opt/conda/envs/Python36/lib/python3.6/site-packages/ibm_cloud_sdk_core/base_service.py\", line 229, in send\n    response.status_code, error_message, http_response=response)\nibm_cloud_sdk_core.api_exception.ApiException: Error: Forbidden, Code: 403\n 74%|\u2588\u2588\u2588\u2588\u2588\u2588\u2588\u258e  | 3943/5347 [27:45<05:09,  4.53it/s]ERROR:root:Forbidden\nTraceback (most recent call last):\n  File \"/opt/conda/envs/Python36/lib/python3.6/site-packages/ibm_cloud_sdk_core/base_service.py\", line 229, in send\n    response.status_code, error_message, http_response=response)\nibm_cloud_sdk_core.api_exception.ApiException: Error: Forbidden, Code: 403\n 74%|\u2588\u2588\u2588\u2588\u2588\u2588\u2588\u258d  | 3944/5347 [27:45<05:06,  4.58it/s]ERROR:root:Forbidden\nTraceback (most recent call last):\n  File \"/opt/conda/envs/Python36/lib/python3.6/site-packages/ibm_cloud_sdk_core/base_service.py\", line 229, in send\n    response.status_code, error_message, http_response=response)\nibm_cloud_sdk_core.api_exception.ApiException: Error: Forbidden, Code: 403\n 74%|\u2588\u2588\u2588\u2588\u2588\u2588\u2588\u258d  | 3945/5347 [27:46<05:21,  4.36it/s]ERROR:root:Forbidden\nTraceback (most recent call last):\n  File \"/opt/conda/envs/Python36/lib/python3.6/site-packages/ibm_cloud_sdk_core/base_service.py\", line 229, in send\n    response.status_code, error_message, http_response=response)\nibm_cloud_sdk_core.api_exception.ApiException: Error: Forbidden, Code: 403\n 74%|\u2588\u2588\u2588\u2588\u2588\u2588\u2588\u258d  | 3946/5347 [27:46<05:13,  4.46it/s]ERROR:root:Forbidden\nTraceback (most recent call last):\n  File \"/opt/conda/envs/Python36/lib/python3.6/site-packages/ibm_cloud_sdk_core/base_service.py\", line 229, in send\n    response.status_code, error_message, http_response=response)\nibm_cloud_sdk_core.api_exception.ApiException: Error: Forbidden, Code: 403\n 74%|\u2588\u2588\u2588\u2588\u2588\u2588\u2588\u258d  | 3947/5347 [27:46<05:08,  4.54it/s]ERROR:root:Forbidden\nTraceback (most recent call last):\n  File \"/opt/conda/envs/Python36/lib/python3.6/site-packages/ibm_cloud_sdk_core/base_service.py\", line 229, in send\n    response.status_code, error_message, http_response=response)\nibm_cloud_sdk_core.api_exception.ApiException: Error: Forbidden, Code: 403\n 74%|\u2588\u2588\u2588\u2588\u2588\u2588\u2588\u258d  | 3948/5347 [27:46<05:02,  4.62it/s]ERROR:root:Forbidden\nTraceback (most recent call last):\n  File \"/opt/conda/envs/Python36/lib/python3.6/site-packages/ibm_cloud_sdk_core/base_service.py\", line 229, in send\n    response.status_code, error_message, http_response=response)\nibm_cloud_sdk_core.api_exception.ApiException: Error: Forbidden, Code: 403\n 74%|\u2588\u2588\u2588\u2588\u2588\u2588\u2588\u258d  | 3949/5347 [27:47<05:15,  4.43it/s]ERROR:root:Forbidden\nTraceback (most recent call last):\n  File \"/opt/conda/envs/Python36/lib/python3.6/site-packages/ibm_cloud_sdk_core/base_service.py\", line 229, in send\n    response.status_code, error_message, http_response=response)\nibm_cloud_sdk_core.api_exception.ApiException: Error: Forbidden, Code: 403\n 74%|\u2588\u2588\u2588\u2588\u2588\u2588\u2588\u258d  | 3950/5347 [27:47<05:13,  4.46it/s]ERROR:root:Forbidden\nTraceback (most recent call last):\n  File \"/opt/conda/envs/Python36/lib/python3.6/site-packages/ibm_cloud_sdk_core/base_service.py\", line 229, in send\n    response.status_code, error_message, http_response=response)\nibm_cloud_sdk_core.api_exception.ApiException: Error: Forbidden, Code: 403\n 74%|\u2588\u2588\u2588\u2588\u2588\u2588\u2588\u258d  | 3951/5347 [27:47<04:53,  4.75it/s]ERROR:root:Forbidden\nTraceback (most recent call last):\n  File \"/opt/conda/envs/Python36/lib/python3.6/site-packages/ibm_cloud_sdk_core/base_service.py\", line 229, in send\n    response.status_code, error_message, http_response=response)\nibm_cloud_sdk_core.api_exception.ApiException: Error: Forbidden, Code: 403\n 74%|\u2588\u2588\u2588\u2588\u2588\u2588\u2588\u258d  | 3952/5347 [27:47<04:49,  4.83it/s]ERROR:root:Forbidden\nTraceback (most recent call last):\n  File \"/opt/conda/envs/Python36/lib/python3.6/site-packages/ibm_cloud_sdk_core/base_service.py\", line 229, in send\n    response.status_code, error_message, http_response=response)\nibm_cloud_sdk_core.api_exception.ApiException: Error: Forbidden, Code: 403\n", "name": "stderr"}, {"output_type": "stream", "text": " 74%|\u2588\u2588\u2588\u2588\u2588\u2588\u2588\u258d  | 3953/5347 [27:47<04:54,  4.74it/s]ERROR:root:Forbidden\nTraceback (most recent call last):\n  File \"/opt/conda/envs/Python36/lib/python3.6/site-packages/ibm_cloud_sdk_core/base_service.py\", line 229, in send\n    response.status_code, error_message, http_response=response)\nibm_cloud_sdk_core.api_exception.ApiException: Error: Forbidden, Code: 403\n 74%|\u2588\u2588\u2588\u2588\u2588\u2588\u2588\u258d  | 3954/5347 [27:48<04:58,  4.66it/s]ERROR:root:Forbidden\nTraceback (most recent call last):\n  File \"/opt/conda/envs/Python36/lib/python3.6/site-packages/ibm_cloud_sdk_core/base_service.py\", line 229, in send\n    response.status_code, error_message, http_response=response)\nibm_cloud_sdk_core.api_exception.ApiException: Error: Forbidden, Code: 403\n 74%|\u2588\u2588\u2588\u2588\u2588\u2588\u2588\u258d  | 3955/5347 [27:48<05:03,  4.59it/s]ERROR:root:Forbidden\nTraceback (most recent call last):\n  File \"/opt/conda/envs/Python36/lib/python3.6/site-packages/ibm_cloud_sdk_core/base_service.py\", line 229, in send\n    response.status_code, error_message, http_response=response)\nibm_cloud_sdk_core.api_exception.ApiException: Error: Forbidden, Code: 403\n 74%|\u2588\u2588\u2588\u2588\u2588\u2588\u2588\u258d  | 3956/5347 [27:48<05:10,  4.48it/s]ERROR:root:Forbidden\nTraceback (most recent call last):\n  File \"/opt/conda/envs/Python36/lib/python3.6/site-packages/ibm_cloud_sdk_core/base_service.py\", line 229, in send\n    response.status_code, error_message, http_response=response)\nibm_cloud_sdk_core.api_exception.ApiException: Error: Forbidden, Code: 403\n 74%|\u2588\u2588\u2588\u2588\u2588\u2588\u2588\u258d  | 3957/5347 [27:48<05:12,  4.45it/s]ERROR:root:Forbidden\nTraceback (most recent call last):\n  File \"/opt/conda/envs/Python36/lib/python3.6/site-packages/ibm_cloud_sdk_core/base_service.py\", line 229, in send\n    response.status_code, error_message, http_response=response)\nibm_cloud_sdk_core.api_exception.ApiException: Error: Forbidden, Code: 403\n 74%|\u2588\u2588\u2588\u2588\u2588\u2588\u2588\u258d  | 3958/5347 [27:48<05:07,  4.52it/s]ERROR:root:Forbidden\nTraceback (most recent call last):\n  File \"/opt/conda/envs/Python36/lib/python3.6/site-packages/ibm_cloud_sdk_core/base_service.py\", line 229, in send\n    response.status_code, error_message, http_response=response)\nibm_cloud_sdk_core.api_exception.ApiException: Error: Forbidden, Code: 403\n 74%|\u2588\u2588\u2588\u2588\u2588\u2588\u2588\u258d  | 3959/5347 [27:49<05:16,  4.39it/s]ERROR:root:Forbidden\nTraceback (most recent call last):\n  File \"/opt/conda/envs/Python36/lib/python3.6/site-packages/ibm_cloud_sdk_core/base_service.py\", line 229, in send\n    response.status_code, error_message, http_response=response)\nibm_cloud_sdk_core.api_exception.ApiException: Error: Forbidden, Code: 403\n 74%|\u2588\u2588\u2588\u2588\u2588\u2588\u2588\u258d  | 3960/5347 [27:49<05:17,  4.37it/s]ERROR:root:Forbidden\nTraceback (most recent call last):\n  File \"/opt/conda/envs/Python36/lib/python3.6/site-packages/ibm_cloud_sdk_core/base_service.py\", line 229, in send\n    response.status_code, error_message, http_response=response)\nibm_cloud_sdk_core.api_exception.ApiException: Error: Forbidden, Code: 403\n 74%|\u2588\u2588\u2588\u2588\u2588\u2588\u2588\u258d  | 3961/5347 [27:49<05:13,  4.42it/s]ERROR:root:Forbidden\nTraceback (most recent call last):\n  File \"/opt/conda/envs/Python36/lib/python3.6/site-packages/ibm_cloud_sdk_core/base_service.py\", line 229, in send\n    response.status_code, error_message, http_response=response)\nibm_cloud_sdk_core.api_exception.ApiException: Error: Forbidden, Code: 403\n 74%|\u2588\u2588\u2588\u2588\u2588\u2588\u2588\u258d  | 3962/5347 [27:49<05:16,  4.37it/s]ERROR:root:Forbidden\nTraceback (most recent call last):\n  File \"/opt/conda/envs/Python36/lib/python3.6/site-packages/ibm_cloud_sdk_core/base_service.py\", line 229, in send\n    response.status_code, error_message, http_response=response)\nibm_cloud_sdk_core.api_exception.ApiException: Error: Forbidden, Code: 403\n 74%|\u2588\u2588\u2588\u2588\u2588\u2588\u2588\u258d  | 3963/5347 [27:50<05:10,  4.46it/s]ERROR:root:Forbidden\nTraceback (most recent call last):\n  File \"/opt/conda/envs/Python36/lib/python3.6/site-packages/ibm_cloud_sdk_core/base_service.py\", line 229, in send\n    response.status_code, error_message, http_response=response)\nibm_cloud_sdk_core.api_exception.ApiException: Error: Forbidden, Code: 403\n 74%|\u2588\u2588\u2588\u2588\u2588\u2588\u2588\u258d  | 3964/5347 [27:50<04:49,  4.77it/s]ERROR:root:Forbidden\nTraceback (most recent call last):\n  File \"/opt/conda/envs/Python36/lib/python3.6/site-packages/ibm_cloud_sdk_core/base_service.py\", line 229, in send\n    response.status_code, error_message, http_response=response)\nibm_cloud_sdk_core.api_exception.ApiException: Error: Forbidden, Code: 403\n 74%|\u2588\u2588\u2588\u2588\u2588\u2588\u2588\u258d  | 3965/5347 [27:50<04:28,  5.15it/s]ERROR:root:Forbidden\nTraceback (most recent call last):\n  File \"/opt/conda/envs/Python36/lib/python3.6/site-packages/ibm_cloud_sdk_core/base_service.py\", line 229, in send\n    response.status_code, error_message, http_response=response)\nibm_cloud_sdk_core.api_exception.ApiException: Error: Forbidden, Code: 403\n 74%|\u2588\u2588\u2588\u2588\u2588\u2588\u2588\u258d  | 3966/5347 [27:50<04:18,  5.34it/s]ERROR:root:Forbidden\nTraceback (most recent call last):\n  File \"/opt/conda/envs/Python36/lib/python3.6/site-packages/ibm_cloud_sdk_core/base_service.py\", line 229, in send\n    response.status_code, error_message, http_response=response)\nibm_cloud_sdk_core.api_exception.ApiException: Error: Forbidden, Code: 403\n 74%|\u2588\u2588\u2588\u2588\u2588\u2588\u2588\u258d  | 3967/5347 [27:50<04:35,  5.02it/s]ERROR:root:Forbidden\nTraceback (most recent call last):\n  File \"/opt/conda/envs/Python36/lib/python3.6/site-packages/ibm_cloud_sdk_core/base_service.py\", line 229, in send\n    response.status_code, error_message, http_response=response)\nibm_cloud_sdk_core.api_exception.ApiException: Error: Forbidden, Code: 403\n 74%|\u2588\u2588\u2588\u2588\u2588\u2588\u2588\u258d  | 3968/5347 [27:51<04:22,  5.25it/s]ERROR:root:Forbidden\nTraceback (most recent call last):\n  File \"/opt/conda/envs/Python36/lib/python3.6/site-packages/ibm_cloud_sdk_core/base_service.py\", line 229, in send\n    response.status_code, error_message, http_response=response)\nibm_cloud_sdk_core.api_exception.ApiException: Error: Forbidden, Code: 403\n 74%|\u2588\u2588\u2588\u2588\u2588\u2588\u2588\u258d  | 3969/5347 [27:51<04:33,  5.04it/s]ERROR:root:Forbidden\nTraceback (most recent call last):\n  File \"/opt/conda/envs/Python36/lib/python3.6/site-packages/ibm_cloud_sdk_core/base_service.py\", line 229, in send\n    response.status_code, error_message, http_response=response)\nibm_cloud_sdk_core.api_exception.ApiException: Error: Forbidden, Code: 403\n 74%|\u2588\u2588\u2588\u2588\u2588\u2588\u2588\u258d  | 3970/5347 [27:51<04:36,  4.98it/s]ERROR:root:Forbidden\nTraceback (most recent call last):\n  File \"/opt/conda/envs/Python36/lib/python3.6/site-packages/ibm_cloud_sdk_core/base_service.py\", line 229, in send\n    response.status_code, error_message, http_response=response)\nibm_cloud_sdk_core.api_exception.ApiException: Error: Forbidden, Code: 403\n 74%|\u2588\u2588\u2588\u2588\u2588\u2588\u2588\u258d  | 3971/5347 [27:51<04:41,  4.88it/s]ERROR:root:Forbidden\nTraceback (most recent call last):\n  File \"/opt/conda/envs/Python36/lib/python3.6/site-packages/ibm_cloud_sdk_core/base_service.py\", line 229, in send\n    response.status_code, error_message, http_response=response)\nibm_cloud_sdk_core.api_exception.ApiException: Error: Forbidden, Code: 403\n 74%|\u2588\u2588\u2588\u2588\u2588\u2588\u2588\u258d  | 3972/5347 [27:51<04:45,  4.82it/s]ERROR:root:Forbidden\nTraceback (most recent call last):\n  File \"/opt/conda/envs/Python36/lib/python3.6/site-packages/ibm_cloud_sdk_core/base_service.py\", line 229, in send\n    response.status_code, error_message, http_response=response)\nibm_cloud_sdk_core.api_exception.ApiException: Error: Forbidden, Code: 403\n 74%|\u2588\u2588\u2588\u2588\u2588\u2588\u2588\u258d  | 3973/5347 [27:52<04:43,  4.84it/s]ERROR:root:Forbidden\nTraceback (most recent call last):\n  File \"/opt/conda/envs/Python36/lib/python3.6/site-packages/ibm_cloud_sdk_core/base_service.py\", line 229, in send\n    response.status_code, error_message, http_response=response)\nibm_cloud_sdk_core.api_exception.ApiException: Error: Forbidden, Code: 403\n 74%|\u2588\u2588\u2588\u2588\u2588\u2588\u2588\u258d  | 3974/5347 [27:52<04:55,  4.65it/s]ERROR:root:Forbidden\nTraceback (most recent call last):\n  File \"/opt/conda/envs/Python36/lib/python3.6/site-packages/ibm_cloud_sdk_core/base_service.py\", line 229, in send\n    response.status_code, error_message, http_response=response)\nibm_cloud_sdk_core.api_exception.ApiException: Error: Forbidden, Code: 403\n 74%|\u2588\u2588\u2588\u2588\u2588\u2588\u2588\u258d  | 3975/5347 [27:52<04:58,  4.60it/s]ERROR:root:Forbidden\nTraceback (most recent call last):\n  File \"/opt/conda/envs/Python36/lib/python3.6/site-packages/ibm_cloud_sdk_core/base_service.py\", line 229, in send\n    response.status_code, error_message, http_response=response)\nibm_cloud_sdk_core.api_exception.ApiException: Error: Forbidden, Code: 403\n", "name": "stderr"}, {"output_type": "stream", "text": " 74%|\u2588\u2588\u2588\u2588\u2588\u2588\u2588\u258d  | 3976/5347 [27:52<04:51,  4.70it/s]ERROR:root:Forbidden\nTraceback (most recent call last):\n  File \"/opt/conda/envs/Python36/lib/python3.6/site-packages/ibm_cloud_sdk_core/base_service.py\", line 229, in send\n    response.status_code, error_message, http_response=response)\nibm_cloud_sdk_core.api_exception.ApiException: Error: Forbidden, Code: 403\n 74%|\u2588\u2588\u2588\u2588\u2588\u2588\u2588\u258d  | 3977/5347 [27:52<04:56,  4.62it/s]ERROR:root:Forbidden\nTraceback (most recent call last):\n  File \"/opt/conda/envs/Python36/lib/python3.6/site-packages/ibm_cloud_sdk_core/base_service.py\", line 229, in send\n    response.status_code, error_message, http_response=response)\nibm_cloud_sdk_core.api_exception.ApiException: Error: Forbidden, Code: 403\n 74%|\u2588\u2588\u2588\u2588\u2588\u2588\u2588\u258d  | 3978/5347 [27:53<04:57,  4.60it/s]ERROR:root:Forbidden\nTraceback (most recent call last):\n  File \"/opt/conda/envs/Python36/lib/python3.6/site-packages/ibm_cloud_sdk_core/base_service.py\", line 229, in send\n    response.status_code, error_message, http_response=response)\nibm_cloud_sdk_core.api_exception.ApiException: Error: Forbidden, Code: 403\n 74%|\u2588\u2588\u2588\u2588\u2588\u2588\u2588\u258d  | 3979/5347 [27:53<05:01,  4.54it/s]ERROR:root:Forbidden\nTraceback (most recent call last):\n  File \"/opt/conda/envs/Python36/lib/python3.6/site-packages/ibm_cloud_sdk_core/base_service.py\", line 229, in send\n    response.status_code, error_message, http_response=response)\nibm_cloud_sdk_core.api_exception.ApiException: Error: Forbidden, Code: 403\n 74%|\u2588\u2588\u2588\u2588\u2588\u2588\u2588\u258d  | 3980/5347 [27:53<05:00,  4.55it/s]ERROR:root:Forbidden\nTraceback (most recent call last):\n  File \"/opt/conda/envs/Python36/lib/python3.6/site-packages/ibm_cloud_sdk_core/base_service.py\", line 229, in send\n    response.status_code, error_message, http_response=response)\nibm_cloud_sdk_core.api_exception.ApiException: Error: Forbidden, Code: 403\n 74%|\u2588\u2588\u2588\u2588\u2588\u2588\u2588\u258d  | 3981/5347 [27:53<04:59,  4.56it/s]ERROR:root:Forbidden\nTraceback (most recent call last):\n  File \"/opt/conda/envs/Python36/lib/python3.6/site-packages/ibm_cloud_sdk_core/base_service.py\", line 229, in send\n    response.status_code, error_message, http_response=response)\nibm_cloud_sdk_core.api_exception.ApiException: Error: Forbidden, Code: 403\n 74%|\u2588\u2588\u2588\u2588\u2588\u2588\u2588\u258d  | 3982/5347 [27:54<05:00,  4.55it/s]ERROR:root:Forbidden\nTraceback (most recent call last):\n  File \"/opt/conda/envs/Python36/lib/python3.6/site-packages/ibm_cloud_sdk_core/base_service.py\", line 229, in send\n    response.status_code, error_message, http_response=response)\nibm_cloud_sdk_core.api_exception.ApiException: Error: Forbidden, Code: 403\n 74%|\u2588\u2588\u2588\u2588\u2588\u2588\u2588\u258d  | 3983/5347 [27:54<05:03,  4.50it/s]ERROR:root:Forbidden\nTraceback (most recent call last):\n  File \"/opt/conda/envs/Python36/lib/python3.6/site-packages/ibm_cloud_sdk_core/base_service.py\", line 229, in send\n    response.status_code, error_message, http_response=response)\nibm_cloud_sdk_core.api_exception.ApiException: Error: Forbidden, Code: 403\n 75%|\u2588\u2588\u2588\u2588\u2588\u2588\u2588\u258d  | 3984/5347 [27:54<04:42,  4.82it/s]ERROR:root:Forbidden\nTraceback (most recent call last):\n  File \"/opt/conda/envs/Python36/lib/python3.6/site-packages/ibm_cloud_sdk_core/base_service.py\", line 229, in send\n    response.status_code, error_message, http_response=response)\nibm_cloud_sdk_core.api_exception.ApiException: Error: Forbidden, Code: 403\n 75%|\u2588\u2588\u2588\u2588\u2588\u2588\u2588\u258d  | 3985/5347 [27:54<04:53,  4.65it/s]ERROR:root:Forbidden\nTraceback (most recent call last):\n  File \"/opt/conda/envs/Python36/lib/python3.6/site-packages/ibm_cloud_sdk_core/base_service.py\", line 229, in send\n    response.status_code, error_message, http_response=response)\nibm_cloud_sdk_core.api_exception.ApiException: Error: Forbidden, Code: 403\n 75%|\u2588\u2588\u2588\u2588\u2588\u2588\u2588\u258d  | 3986/5347 [27:54<04:53,  4.64it/s]ERROR:root:Forbidden\nTraceback (most recent call last):\n  File \"/opt/conda/envs/Python36/lib/python3.6/site-packages/ibm_cloud_sdk_core/base_service.py\", line 229, in send\n    response.status_code, error_message, http_response=response)\nibm_cloud_sdk_core.api_exception.ApiException: Error: Forbidden, Code: 403\n 75%|\u2588\u2588\u2588\u2588\u2588\u2588\u2588\u258d  | 3987/5347 [27:55<04:54,  4.62it/s]ERROR:root:Forbidden\nTraceback (most recent call last):\n  File \"/opt/conda/envs/Python36/lib/python3.6/site-packages/ibm_cloud_sdk_core/base_service.py\", line 229, in send\n    response.status_code, error_message, http_response=response)\nibm_cloud_sdk_core.api_exception.ApiException: Error: Forbidden, Code: 403\n 75%|\u2588\u2588\u2588\u2588\u2588\u2588\u2588\u258d  | 3988/5347 [27:55<04:49,  4.69it/s]ERROR:root:Forbidden\nTraceback (most recent call last):\n  File \"/opt/conda/envs/Python36/lib/python3.6/site-packages/ibm_cloud_sdk_core/base_service.py\", line 229, in send\n    response.status_code, error_message, http_response=response)\nibm_cloud_sdk_core.api_exception.ApiException: Error: Forbidden, Code: 403\n 75%|\u2588\u2588\u2588\u2588\u2588\u2588\u2588\u258d  | 3989/5347 [27:55<04:43,  4.78it/s]ERROR:root:Forbidden\nTraceback (most recent call last):\n  File \"/opt/conda/envs/Python36/lib/python3.6/site-packages/ibm_cloud_sdk_core/base_service.py\", line 229, in send\n    response.status_code, error_message, http_response=response)\nibm_cloud_sdk_core.api_exception.ApiException: Error: Forbidden, Code: 403\n 75%|\u2588\u2588\u2588\u2588\u2588\u2588\u2588\u258d  | 3990/5347 [27:55<04:39,  4.85it/s]ERROR:root:Forbidden\nTraceback (most recent call last):\n  File \"/opt/conda/envs/Python36/lib/python3.6/site-packages/ibm_cloud_sdk_core/base_service.py\", line 229, in send\n    response.status_code, error_message, http_response=response)\nibm_cloud_sdk_core.api_exception.ApiException: Error: Forbidden, Code: 403\n 75%|\u2588\u2588\u2588\u2588\u2588\u2588\u2588\u258d  | 3991/5347 [27:55<04:50,  4.67it/s]ERROR:root:Forbidden\nTraceback (most recent call last):\n  File \"/opt/conda/envs/Python36/lib/python3.6/site-packages/ibm_cloud_sdk_core/base_service.py\", line 229, in send\n    response.status_code, error_message, http_response=response)\nibm_cloud_sdk_core.api_exception.ApiException: Error: Forbidden, Code: 403\n 75%|\u2588\u2588\u2588\u2588\u2588\u2588\u2588\u258d  | 3992/5347 [27:56<04:50,  4.66it/s]ERROR:root:Forbidden\nTraceback (most recent call last):\n  File \"/opt/conda/envs/Python36/lib/python3.6/site-packages/ibm_cloud_sdk_core/base_service.py\", line 229, in send\n    response.status_code, error_message, http_response=response)\nibm_cloud_sdk_core.api_exception.ApiException: Error: Forbidden, Code: 403\n 75%|\u2588\u2588\u2588\u2588\u2588\u2588\u2588\u258d  | 3993/5347 [27:56<04:53,  4.61it/s]ERROR:root:Forbidden\nTraceback (most recent call last):\n  File \"/opt/conda/envs/Python36/lib/python3.6/site-packages/ibm_cloud_sdk_core/base_service.py\", line 229, in send\n    response.status_code, error_message, http_response=response)\nibm_cloud_sdk_core.api_exception.ApiException: Error: Forbidden, Code: 403\n 75%|\u2588\u2588\u2588\u2588\u2588\u2588\u2588\u258d  | 3994/5347 [27:56<04:52,  4.63it/s]ERROR:root:Forbidden\nTraceback (most recent call last):\n  File \"/opt/conda/envs/Python36/lib/python3.6/site-packages/ibm_cloud_sdk_core/base_service.py\", line 229, in send\n    response.status_code, error_message, http_response=response)\nibm_cloud_sdk_core.api_exception.ApiException: Error: Forbidden, Code: 403\n 75%|\u2588\u2588\u2588\u2588\u2588\u2588\u2588\u258d  | 3995/5347 [27:56<04:58,  4.53it/s]ERROR:root:Forbidden\nTraceback (most recent call last):\n  File \"/opt/conda/envs/Python36/lib/python3.6/site-packages/ibm_cloud_sdk_core/base_service.py\", line 229, in send\n    response.status_code, error_message, http_response=response)\nibm_cloud_sdk_core.api_exception.ApiException: Error: Forbidden, Code: 403\n 75%|\u2588\u2588\u2588\u2588\u2588\u2588\u2588\u258d  | 3996/5347 [27:57<05:01,  4.49it/s]ERROR:root:Forbidden\nTraceback (most recent call last):\n  File \"/opt/conda/envs/Python36/lib/python3.6/site-packages/ibm_cloud_sdk_core/base_service.py\", line 229, in send\n    response.status_code, error_message, http_response=response)\nibm_cloud_sdk_core.api_exception.ApiException: Error: Forbidden, Code: 403\n 75%|\u2588\u2588\u2588\u2588\u2588\u2588\u2588\u258d  | 3997/5347 [27:57<05:00,  4.49it/s]ERROR:root:Forbidden\nTraceback (most recent call last):\n  File \"/opt/conda/envs/Python36/lib/python3.6/site-packages/ibm_cloud_sdk_core/base_service.py\", line 229, in send\n    response.status_code, error_message, http_response=response)\nibm_cloud_sdk_core.api_exception.ApiException: Error: Forbidden, Code: 403\n 75%|\u2588\u2588\u2588\u2588\u2588\u2588\u2588\u258d  | 3998/5347 [27:57<04:57,  4.53it/s]ERROR:root:Forbidden\nTraceback (most recent call last):\n  File \"/opt/conda/envs/Python36/lib/python3.6/site-packages/ibm_cloud_sdk_core/base_service.py\", line 229, in send\n    response.status_code, error_message, http_response=response)\nibm_cloud_sdk_core.api_exception.ApiException: Error: Forbidden, Code: 403\n", "name": "stderr"}, {"output_type": "stream", "text": " 75%|\u2588\u2588\u2588\u2588\u2588\u2588\u2588\u258d  | 3999/5347 [27:57<04:58,  4.51it/s]ERROR:root:Forbidden\nTraceback (most recent call last):\n  File \"/opt/conda/envs/Python36/lib/python3.6/site-packages/ibm_cloud_sdk_core/base_service.py\", line 229, in send\n    response.status_code, error_message, http_response=response)\nibm_cloud_sdk_core.api_exception.ApiException: Error: Forbidden, Code: 403\n 75%|\u2588\u2588\u2588\u2588\u2588\u2588\u2588\u258d  | 4000/5347 [27:57<04:58,  4.52it/s]ERROR:root:Forbidden\nTraceback (most recent call last):\n  File \"/opt/conda/envs/Python36/lib/python3.6/site-packages/ibm_cloud_sdk_core/base_service.py\", line 229, in send\n    response.status_code, error_message, http_response=response)\nibm_cloud_sdk_core.api_exception.ApiException: Error: Forbidden, Code: 403\n 75%|\u2588\u2588\u2588\u2588\u2588\u2588\u2588\u258d  | 4001/5347 [27:58<04:57,  4.52it/s]ERROR:root:Forbidden\nTraceback (most recent call last):\n  File \"/opt/conda/envs/Python36/lib/python3.6/site-packages/ibm_cloud_sdk_core/base_service.py\", line 229, in send\n    response.status_code, error_message, http_response=response)\nibm_cloud_sdk_core.api_exception.ApiException: Error: Forbidden, Code: 403\n 75%|\u2588\u2588\u2588\u2588\u2588\u2588\u2588\u258d  | 4002/5347 [27:58<05:03,  4.44it/s]ERROR:root:Forbidden\nTraceback (most recent call last):\n  File \"/opt/conda/envs/Python36/lib/python3.6/site-packages/ibm_cloud_sdk_core/base_service.py\", line 229, in send\n    response.status_code, error_message, http_response=response)\nibm_cloud_sdk_core.api_exception.ApiException: Error: Forbidden, Code: 403\n 75%|\u2588\u2588\u2588\u2588\u2588\u2588\u2588\u258d  | 4003/5347 [27:58<05:03,  4.42it/s]ERROR:root:Forbidden\nTraceback (most recent call last):\n  File \"/opt/conda/envs/Python36/lib/python3.6/site-packages/ibm_cloud_sdk_core/base_service.py\", line 229, in send\n    response.status_code, error_message, http_response=response)\nibm_cloud_sdk_core.api_exception.ApiException: Error: Forbidden, Code: 403\n 75%|\u2588\u2588\u2588\u2588\u2588\u2588\u2588\u258d  | 4004/5347 [27:59<07:05,  3.16it/s]ERROR:root:Forbidden\nTraceback (most recent call last):\n  File \"/opt/conda/envs/Python36/lib/python3.6/site-packages/ibm_cloud_sdk_core/base_service.py\", line 229, in send\n    response.status_code, error_message, http_response=response)\nibm_cloud_sdk_core.api_exception.ApiException: Error: Forbidden, Code: 403\n 75%|\u2588\u2588\u2588\u2588\u2588\u2588\u2588\u258d  | 4005/5347 [27:59<06:24,  3.49it/s]ERROR:root:Forbidden\nTraceback (most recent call last):\n  File \"/opt/conda/envs/Python36/lib/python3.6/site-packages/ibm_cloud_sdk_core/base_service.py\", line 229, in send\n    response.status_code, error_message, http_response=response)\nibm_cloud_sdk_core.api_exception.ApiException: Error: Forbidden, Code: 403\n 75%|\u2588\u2588\u2588\u2588\u2588\u2588\u2588\u258d  | 4006/5347 [27:59<06:01,  3.71it/s]ERROR:root:Forbidden\nTraceback (most recent call last):\n  File \"/opt/conda/envs/Python36/lib/python3.6/site-packages/ibm_cloud_sdk_core/base_service.py\", line 229, in send\n    response.status_code, error_message, http_response=response)\nibm_cloud_sdk_core.api_exception.ApiException: Error: Forbidden, Code: 403\n 75%|\u2588\u2588\u2588\u2588\u2588\u2588\u2588\u258d  | 4007/5347 [28:00<07:52,  2.84it/s]ERROR:root:Forbidden\nTraceback (most recent call last):\n  File \"/opt/conda/envs/Python36/lib/python3.6/site-packages/ibm_cloud_sdk_core/base_service.py\", line 229, in send\n    response.status_code, error_message, http_response=response)\nibm_cloud_sdk_core.api_exception.ApiException: Error: Forbidden, Code: 403\n 75%|\u2588\u2588\u2588\u2588\u2588\u2588\u2588\u258d  | 4008/5347 [28:00<06:56,  3.21it/s]ERROR:root:Forbidden\nTraceback (most recent call last):\n  File \"/opt/conda/envs/Python36/lib/python3.6/site-packages/ibm_cloud_sdk_core/base_service.py\", line 229, in send\n    response.status_code, error_message, http_response=response)\nibm_cloud_sdk_core.api_exception.ApiException: Error: Forbidden, Code: 403\n 75%|\u2588\u2588\u2588\u2588\u2588\u2588\u2588\u258d  | 4009/5347 [28:00<06:26,  3.47it/s]ERROR:root:Forbidden\nTraceback (most recent call last):\n  File \"/opt/conda/envs/Python36/lib/python3.6/site-packages/ibm_cloud_sdk_core/base_service.py\", line 229, in send\n    response.status_code, error_message, http_response=response)\nibm_cloud_sdk_core.api_exception.ApiException: Error: Forbidden, Code: 403\n 75%|\u2588\u2588\u2588\u2588\u2588\u2588\u2588\u258d  | 4010/5347 [28:01<07:23,  3.01it/s]ERROR:root:Forbidden\nTraceback (most recent call last):\n  File \"/opt/conda/envs/Python36/lib/python3.6/site-packages/ibm_cloud_sdk_core/base_service.py\", line 229, in send\n    response.status_code, error_message, http_response=response)\nibm_cloud_sdk_core.api_exception.ApiException: Error: Forbidden, Code: 403\n 75%|\u2588\u2588\u2588\u2588\u2588\u2588\u2588\u258c  | 4011/5347 [28:01<08:01,  2.78it/s]ERROR:root:Forbidden\nTraceback (most recent call last):\n  File \"/opt/conda/envs/Python36/lib/python3.6/site-packages/ibm_cloud_sdk_core/base_service.py\", line 229, in send\n    response.status_code, error_message, http_response=response)\nibm_cloud_sdk_core.api_exception.ApiException: Error: Forbidden, Code: 403\n 75%|\u2588\u2588\u2588\u2588\u2588\u2588\u2588\u258c  | 4012/5347 [28:01<06:59,  3.18it/s]ERROR:root:Forbidden\nTraceback (most recent call last):\n  File \"/opt/conda/envs/Python36/lib/python3.6/site-packages/ibm_cloud_sdk_core/base_service.py\", line 229, in send\n    response.status_code, error_message, http_response=response)\nibm_cloud_sdk_core.api_exception.ApiException: Error: Forbidden, Code: 403\n 75%|\u2588\u2588\u2588\u2588\u2588\u2588\u2588\u258c  | 4013/5347 [28:01<06:22,  3.49it/s]ERROR:root:Forbidden\nTraceback (most recent call last):\n  File \"/opt/conda/envs/Python36/lib/python3.6/site-packages/ibm_cloud_sdk_core/base_service.py\", line 229, in send\n    response.status_code, error_message, http_response=response)\nibm_cloud_sdk_core.api_exception.ApiException: Error: Forbidden, Code: 403\n 75%|\u2588\u2588\u2588\u2588\u2588\u2588\u2588\u258c  | 4014/5347 [28:02<06:05,  3.64it/s]ERROR:root:Forbidden\nTraceback (most recent call last):\n  File \"/opt/conda/envs/Python36/lib/python3.6/site-packages/ibm_cloud_sdk_core/base_service.py\", line 229, in send\n    response.status_code, error_message, http_response=response)\nibm_cloud_sdk_core.api_exception.ApiException: Error: Forbidden, Code: 403\n 75%|\u2588\u2588\u2588\u2588\u2588\u2588\u2588\u258c  | 4015/5347 [28:02<05:29,  4.04it/s]ERROR:root:Forbidden\nTraceback (most recent call last):\n  File \"/opt/conda/envs/Python36/lib/python3.6/site-packages/ibm_cloud_sdk_core/base_service.py\", line 229, in send\n    response.status_code, error_message, http_response=response)\nibm_cloud_sdk_core.api_exception.ApiException: Error: Forbidden, Code: 403\n 75%|\u2588\u2588\u2588\u2588\u2588\u2588\u2588\u258c  | 4016/5347 [28:02<05:05,  4.36it/s]ERROR:root:Forbidden\nTraceback (most recent call last):\n  File \"/opt/conda/envs/Python36/lib/python3.6/site-packages/ibm_cloud_sdk_core/base_service.py\", line 229, in send\n    response.status_code, error_message, http_response=response)\nibm_cloud_sdk_core.api_exception.ApiException: Error: Forbidden, Code: 403\n 75%|\u2588\u2588\u2588\u2588\u2588\u2588\u2588\u258c  | 4017/5347 [28:02<06:25,  3.45it/s]ERROR:root:Forbidden\nTraceback (most recent call last):\n  File \"/opt/conda/envs/Python36/lib/python3.6/site-packages/ibm_cloud_sdk_core/base_service.py\", line 229, in send\n    response.status_code, error_message, http_response=response)\nibm_cloud_sdk_core.api_exception.ApiException: Error: Forbidden, Code: 403\n 75%|\u2588\u2588\u2588\u2588\u2588\u2588\u2588\u258c  | 4018/5347 [28:03<07:12,  3.07it/s]ERROR:root:Forbidden\nTraceback (most recent call last):\n  File \"/opt/conda/envs/Python36/lib/python3.6/site-packages/ibm_cloud_sdk_core/base_service.py\", line 229, in send\n    response.status_code, error_message, http_response=response)\nibm_cloud_sdk_core.api_exception.ApiException: Error: Forbidden, Code: 403\n 75%|\u2588\u2588\u2588\u2588\u2588\u2588\u2588\u258c  | 4019/5347 [28:05<17:13,  1.28it/s]ERROR:root:Forbidden\nTraceback (most recent call last):\n  File \"/opt/conda/envs/Python36/lib/python3.6/site-packages/ibm_cloud_sdk_core/base_service.py\", line 229, in send\n    response.status_code, error_message, http_response=response)\nibm_cloud_sdk_core.api_exception.ApiException: Error: Forbidden, Code: 403\n 75%|\u2588\u2588\u2588\u2588\u2588\u2588\u2588\u258c  | 4020/5347 [28:05<13:23,  1.65it/s]ERROR:root:Forbidden\nTraceback (most recent call last):\n  File \"/opt/conda/envs/Python36/lib/python3.6/site-packages/ibm_cloud_sdk_core/base_service.py\", line 229, in send\n    response.status_code, error_message, http_response=response)\nibm_cloud_sdk_core.api_exception.ApiException: Error: Forbidden, Code: 403\n 75%|\u2588\u2588\u2588\u2588\u2588\u2588\u2588\u258c  | 4021/5347 [28:05<12:04,  1.83it/s]ERROR:root:Forbidden\nTraceback (most recent call last):\n  File \"/opt/conda/envs/Python36/lib/python3.6/site-packages/ibm_cloud_sdk_core/base_service.py\", line 229, in send\n    response.status_code, error_message, http_response=response)\nibm_cloud_sdk_core.api_exception.ApiException: Error: Forbidden, Code: 403\n", "name": "stderr"}, {"output_type": "stream", "text": " 75%|\u2588\u2588\u2588\u2588\u2588\u2588\u2588\u258c  | 4022/5347 [28:06<09:43,  2.27it/s]ERROR:root:Forbidden\nTraceback (most recent call last):\n  File \"/opt/conda/envs/Python36/lib/python3.6/site-packages/ibm_cloud_sdk_core/base_service.py\", line 229, in send\n    response.status_code, error_message, http_response=response)\nibm_cloud_sdk_core.api_exception.ApiException: Error: Forbidden, Code: 403\n 75%|\u2588\u2588\u2588\u2588\u2588\u2588\u2588\u258c  | 4023/5347 [28:06<08:26,  2.62it/s]ERROR:root:Forbidden\nTraceback (most recent call last):\n  File \"/opt/conda/envs/Python36/lib/python3.6/site-packages/ibm_cloud_sdk_core/base_service.py\", line 229, in send\n    response.status_code, error_message, http_response=response)\nibm_cloud_sdk_core.api_exception.ApiException: Error: Forbidden, Code: 403\n 75%|\u2588\u2588\u2588\u2588\u2588\u2588\u2588\u258c  | 4024/5347 [28:06<07:22,  2.99it/s]ERROR:root:Forbidden\nTraceback (most recent call last):\n  File \"/opt/conda/envs/Python36/lib/python3.6/site-packages/ibm_cloud_sdk_core/base_service.py\", line 229, in send\n    response.status_code, error_message, http_response=response)\nibm_cloud_sdk_core.api_exception.ApiException: Error: Forbidden, Code: 403\n 75%|\u2588\u2588\u2588\u2588\u2588\u2588\u2588\u258c  | 4025/5347 [28:06<06:48,  3.24it/s]ERROR:root:Forbidden\nTraceback (most recent call last):\n  File \"/opt/conda/envs/Python36/lib/python3.6/site-packages/ibm_cloud_sdk_core/base_service.py\", line 229, in send\n    response.status_code, error_message, http_response=response)\nibm_cloud_sdk_core.api_exception.ApiException: Error: Forbidden, Code: 403\n 75%|\u2588\u2588\u2588\u2588\u2588\u2588\u2588\u258c  | 4026/5347 [28:07<07:33,  2.91it/s]ERROR:root:Forbidden\nTraceback (most recent call last):\n  File \"/opt/conda/envs/Python36/lib/python3.6/site-packages/ibm_cloud_sdk_core/base_service.py\", line 229, in send\n    response.status_code, error_message, http_response=response)\nibm_cloud_sdk_core.api_exception.ApiException: Error: Forbidden, Code: 403\n 75%|\u2588\u2588\u2588\u2588\u2588\u2588\u2588\u258c  | 4027/5347 [28:07<08:02,  2.73it/s]ERROR:root:Forbidden\nTraceback (most recent call last):\n  File \"/opt/conda/envs/Python36/lib/python3.6/site-packages/ibm_cloud_sdk_core/base_service.py\", line 229, in send\n    response.status_code, error_message, http_response=response)\nibm_cloud_sdk_core.api_exception.ApiException: Error: Forbidden, Code: 403\n 75%|\u2588\u2588\u2588\u2588\u2588\u2588\u2588\u258c  | 4028/5347 [28:07<07:07,  3.09it/s]ERROR:root:Forbidden\nTraceback (most recent call last):\n  File \"/opt/conda/envs/Python36/lib/python3.6/site-packages/ibm_cloud_sdk_core/base_service.py\", line 229, in send\n    response.status_code, error_message, http_response=response)\nibm_cloud_sdk_core.api_exception.ApiException: Error: Forbidden, Code: 403\n 75%|\u2588\u2588\u2588\u2588\u2588\u2588\u2588\u258c  | 4029/5347 [28:08<06:26,  3.41it/s]ERROR:root:Forbidden\nTraceback (most recent call last):\n  File \"/opt/conda/envs/Python36/lib/python3.6/site-packages/ibm_cloud_sdk_core/base_service.py\", line 229, in send\n    response.status_code, error_message, http_response=response)\nibm_cloud_sdk_core.api_exception.ApiException: Error: Forbidden, Code: 403\n 75%|\u2588\u2588\u2588\u2588\u2588\u2588\u2588\u258c  | 4030/5347 [28:08<07:12,  3.04it/s]ERROR:root:Forbidden\nTraceback (most recent call last):\n  File \"/opt/conda/envs/Python36/lib/python3.6/site-packages/ibm_cloud_sdk_core/base_service.py\", line 229, in send\n    response.status_code, error_message, http_response=response)\nibm_cloud_sdk_core.api_exception.ApiException: Error: Forbidden, Code: 403\n 75%|\u2588\u2588\u2588\u2588\u2588\u2588\u2588\u258c  | 4031/5347 [28:08<06:32,  3.36it/s]ERROR:root:Forbidden\nTraceback (most recent call last):\n  File \"/opt/conda/envs/Python36/lib/python3.6/site-packages/ibm_cloud_sdk_core/base_service.py\", line 229, in send\n    response.status_code, error_message, http_response=response)\nibm_cloud_sdk_core.api_exception.ApiException: Error: Forbidden, Code: 403\n 75%|\u2588\u2588\u2588\u2588\u2588\u2588\u2588\u258c  | 4032/5347 [28:08<05:56,  3.69it/s]ERROR:root:Forbidden\nTraceback (most recent call last):\n  File \"/opt/conda/envs/Python36/lib/python3.6/site-packages/ibm_cloud_sdk_core/base_service.py\", line 229, in send\n    response.status_code, error_message, http_response=response)\nibm_cloud_sdk_core.api_exception.ApiException: Error: Forbidden, Code: 403\n 75%|\u2588\u2588\u2588\u2588\u2588\u2588\u2588\u258c  | 4033/5347 [28:09<06:55,  3.16it/s]ERROR:root:Forbidden\nTraceback (most recent call last):\n  File \"/opt/conda/envs/Python36/lib/python3.6/site-packages/ibm_cloud_sdk_core/base_service.py\", line 229, in send\n    response.status_code, error_message, http_response=response)\nibm_cloud_sdk_core.api_exception.ApiException: Error: Forbidden, Code: 403\n 75%|\u2588\u2588\u2588\u2588\u2588\u2588\u2588\u258c  | 4034/5347 [28:09<05:56,  3.68it/s]ERROR:root:Forbidden\nTraceback (most recent call last):\n  File \"/opt/conda/envs/Python36/lib/python3.6/site-packages/ibm_cloud_sdk_core/base_service.py\", line 229, in send\n    response.status_code, error_message, http_response=response)\nibm_cloud_sdk_core.api_exception.ApiException: Error: Forbidden, Code: 403\n 75%|\u2588\u2588\u2588\u2588\u2588\u2588\u2588\u258c  | 4035/5347 [28:09<05:40,  3.86it/s]ERROR:root:Forbidden\nTraceback (most recent call last):\n  File \"/opt/conda/envs/Python36/lib/python3.6/site-packages/ibm_cloud_sdk_core/base_service.py\", line 229, in send\n    response.status_code, error_message, http_response=response)\nibm_cloud_sdk_core.api_exception.ApiException: Error: Forbidden, Code: 403\n 75%|\u2588\u2588\u2588\u2588\u2588\u2588\u2588\u258c  | 4036/5347 [28:09<05:29,  3.98it/s]ERROR:root:Forbidden\nTraceback (most recent call last):\n  File \"/opt/conda/envs/Python36/lib/python3.6/site-packages/ibm_cloud_sdk_core/base_service.py\", line 229, in send\n    response.status_code, error_message, http_response=response)\nibm_cloud_sdk_core.api_exception.ApiException: Error: Forbidden, Code: 403\n 76%|\u2588\u2588\u2588\u2588\u2588\u2588\u2588\u258c  | 4037/5347 [28:10<06:31,  3.35it/s]ERROR:root:Forbidden\nTraceback (most recent call last):\n  File \"/opt/conda/envs/Python36/lib/python3.6/site-packages/ibm_cloud_sdk_core/base_service.py\", line 229, in send\n    response.status_code, error_message, http_response=response)\nibm_cloud_sdk_core.api_exception.ApiException: Error: Forbidden, Code: 403\n 76%|\u2588\u2588\u2588\u2588\u2588\u2588\u2588\u258c  | 4038/5347 [28:10<07:19,  2.98it/s]ERROR:root:Forbidden\nTraceback (most recent call last):\n  File \"/opt/conda/envs/Python36/lib/python3.6/site-packages/ibm_cloud_sdk_core/base_service.py\", line 229, in send\n    response.status_code, error_message, http_response=response)\nibm_cloud_sdk_core.api_exception.ApiException: Error: Forbidden, Code: 403\n 76%|\u2588\u2588\u2588\u2588\u2588\u2588\u2588\u258c  | 4039/5347 [28:11<07:52,  2.77it/s]ERROR:root:Forbidden\nTraceback (most recent call last):\n  File \"/opt/conda/envs/Python36/lib/python3.6/site-packages/ibm_cloud_sdk_core/base_service.py\", line 229, in send\n    response.status_code, error_message, http_response=response)\nibm_cloud_sdk_core.api_exception.ApiException: Error: Forbidden, Code: 403\n 76%|\u2588\u2588\u2588\u2588\u2588\u2588\u2588\u258c  | 4040/5347 [28:11<06:59,  3.12it/s]ERROR:root:Forbidden\nTraceback (most recent call last):\n  File \"/opt/conda/envs/Python36/lib/python3.6/site-packages/ibm_cloud_sdk_core/base_service.py\", line 229, in send\n    response.status_code, error_message, http_response=response)\nibm_cloud_sdk_core.api_exception.ApiException: Error: Forbidden, Code: 403\n 76%|\u2588\u2588\u2588\u2588\u2588\u2588\u2588\u258c  | 4041/5347 [28:11<07:33,  2.88it/s]ERROR:root:Forbidden\nTraceback (most recent call last):\n  File \"/opt/conda/envs/Python36/lib/python3.6/site-packages/ibm_cloud_sdk_core/base_service.py\", line 229, in send\n    response.status_code, error_message, http_response=response)\nibm_cloud_sdk_core.api_exception.ApiException: Error: Forbidden, Code: 403\n 76%|\u2588\u2588\u2588\u2588\u2588\u2588\u2588\u258c  | 4042/5347 [28:12<08:03,  2.70it/s]ERROR:root:Forbidden\nTraceback (most recent call last):\n  File \"/opt/conda/envs/Python36/lib/python3.6/site-packages/ibm_cloud_sdk_core/base_service.py\", line 229, in send\n    response.status_code, error_message, http_response=response)\nibm_cloud_sdk_core.api_exception.ApiException: Error: Forbidden, Code: 403\n 76%|\u2588\u2588\u2588\u2588\u2588\u2588\u2588\u258c  | 4043/5347 [28:12<06:52,  3.16it/s]ERROR:root:Forbidden\nTraceback (most recent call last):\n  File \"/opt/conda/envs/Python36/lib/python3.6/site-packages/ibm_cloud_sdk_core/base_service.py\", line 229, in send\n    response.status_code, error_message, http_response=response)\nibm_cloud_sdk_core.api_exception.ApiException: Error: Forbidden, Code: 403\n 76%|\u2588\u2588\u2588\u2588\u2588\u2588\u2588\u258c  | 4044/5347 [28:12<07:43,  2.81it/s]ERROR:root:Forbidden\nTraceback (most recent call last):\n  File \"/opt/conda/envs/Python36/lib/python3.6/site-packages/ibm_cloud_sdk_core/base_service.py\", line 229, in send\n    response.status_code, error_message, http_response=response)\nibm_cloud_sdk_core.api_exception.ApiException: Error: Forbidden, Code: 403\n", "name": "stderr"}, {"output_type": "stream", "text": " 76%|\u2588\u2588\u2588\u2588\u2588\u2588\u2588\u258c  | 4045/5347 [28:13<06:36,  3.29it/s]ERROR:root:Forbidden\nTraceback (most recent call last):\n  File \"/opt/conda/envs/Python36/lib/python3.6/site-packages/ibm_cloud_sdk_core/base_service.py\", line 229, in send\n    response.status_code, error_message, http_response=response)\nibm_cloud_sdk_core.api_exception.ApiException: Error: Forbidden, Code: 403\n 76%|\u2588\u2588\u2588\u2588\u2588\u2588\u2588\u258c  | 4046/5347 [28:13<05:49,  3.73it/s]ERROR:root:Forbidden\nTraceback (most recent call last):\n  File \"/opt/conda/envs/Python36/lib/python3.6/site-packages/ibm_cloud_sdk_core/base_service.py\", line 229, in send\n    response.status_code, error_message, http_response=response)\nibm_cloud_sdk_core.api_exception.ApiException: Error: Forbidden, Code: 403\n 76%|\u2588\u2588\u2588\u2588\u2588\u2588\u2588\u258c  | 4047/5347 [28:13<06:50,  3.16it/s]ERROR:root:Forbidden\nTraceback (most recent call last):\n  File \"/opt/conda/envs/Python36/lib/python3.6/site-packages/ibm_cloud_sdk_core/base_service.py\", line 229, in send\n    response.status_code, error_message, http_response=response)\nibm_cloud_sdk_core.api_exception.ApiException: Error: Forbidden, Code: 403\n 76%|\u2588\u2588\u2588\u2588\u2588\u2588\u2588\u258c  | 4048/5347 [28:13<06:01,  3.60it/s]ERROR:root:Forbidden\nTraceback (most recent call last):\n  File \"/opt/conda/envs/Python36/lib/python3.6/site-packages/ibm_cloud_sdk_core/base_service.py\", line 229, in send\n    response.status_code, error_message, http_response=response)\nibm_cloud_sdk_core.api_exception.ApiException: Error: Forbidden, Code: 403\n 76%|\u2588\u2588\u2588\u2588\u2588\u2588\u2588\u258c  | 4049/5347 [28:14<06:53,  3.14it/s]ERROR:root:Forbidden\nTraceback (most recent call last):\n  File \"/opt/conda/envs/Python36/lib/python3.6/site-packages/ibm_cloud_sdk_core/base_service.py\", line 229, in send\n    response.status_code, error_message, http_response=response)\nibm_cloud_sdk_core.api_exception.ApiException: Error: Forbidden, Code: 403\n 76%|\u2588\u2588\u2588\u2588\u2588\u2588\u2588\u258c  | 4050/5347 [28:14<06:15,  3.45it/s]ERROR:root:Forbidden\nTraceback (most recent call last):\n  File \"/opt/conda/envs/Python36/lib/python3.6/site-packages/ibm_cloud_sdk_core/base_service.py\", line 229, in send\n    response.status_code, error_message, http_response=response)\nibm_cloud_sdk_core.api_exception.ApiException: Error: Forbidden, Code: 403\n 76%|\u2588\u2588\u2588\u2588\u2588\u2588\u2588\u258c  | 4051/5347 [28:14<07:02,  3.07it/s]ERROR:root:Forbidden\nTraceback (most recent call last):\n  File \"/opt/conda/envs/Python36/lib/python3.6/site-packages/ibm_cloud_sdk_core/base_service.py\", line 229, in send\n    response.status_code, error_message, http_response=response)\nibm_cloud_sdk_core.api_exception.ApiException: Error: Forbidden, Code: 403\n 76%|\u2588\u2588\u2588\u2588\u2588\u2588\u2588\u258c  | 4052/5347 [28:15<06:12,  3.48it/s]ERROR:root:Forbidden\nTraceback (most recent call last):\n  File \"/opt/conda/envs/Python36/lib/python3.6/site-packages/ibm_cloud_sdk_core/base_service.py\", line 229, in send\n    response.status_code, error_message, http_response=response)\nibm_cloud_sdk_core.api_exception.ApiException: Error: Forbidden, Code: 403\n 76%|\u2588\u2588\u2588\u2588\u2588\u2588\u2588\u258c  | 4053/5347 [28:15<05:29,  3.93it/s]ERROR:root:Forbidden\nTraceback (most recent call last):\n  File \"/opt/conda/envs/Python36/lib/python3.6/site-packages/ibm_cloud_sdk_core/base_service.py\", line 229, in send\n    response.status_code, error_message, http_response=response)\nibm_cloud_sdk_core.api_exception.ApiException: Error: Forbidden, Code: 403\n 76%|\u2588\u2588\u2588\u2588\u2588\u2588\u2588\u258c  | 4054/5347 [28:15<06:30,  3.31it/s]ERROR:root:Forbidden\nTraceback (most recent call last):\n  File \"/opt/conda/envs/Python36/lib/python3.6/site-packages/ibm_cloud_sdk_core/base_service.py\", line 229, in send\n    response.status_code, error_message, http_response=response)\nibm_cloud_sdk_core.api_exception.ApiException: Error: Forbidden, Code: 403\n 76%|\u2588\u2588\u2588\u2588\u2588\u2588\u2588\u258c  | 4055/5347 [28:16<07:13,  2.98it/s]ERROR:root:Forbidden\nTraceback (most recent call last):\n  File \"/opt/conda/envs/Python36/lib/python3.6/site-packages/ibm_cloud_sdk_core/base_service.py\", line 229, in send\n    response.status_code, error_message, http_response=response)\nibm_cloud_sdk_core.api_exception.ApiException: Error: Forbidden, Code: 403\n 76%|\u2588\u2588\u2588\u2588\u2588\u2588\u2588\u258c  | 4056/5347 [28:16<06:45,  3.19it/s]ERROR:root:Forbidden\nTraceback (most recent call last):\n  File \"/opt/conda/envs/Python36/lib/python3.6/site-packages/ibm_cloud_sdk_core/base_service.py\", line 229, in send\n    response.status_code, error_message, http_response=response)\nibm_cloud_sdk_core.api_exception.ApiException: Error: Forbidden, Code: 403\n 76%|\u2588\u2588\u2588\u2588\u2588\u2588\u2588\u258c  | 4057/5347 [28:16<06:17,  3.42it/s]ERROR:root:Forbidden\nTraceback (most recent call last):\n  File \"/opt/conda/envs/Python36/lib/python3.6/site-packages/ibm_cloud_sdk_core/base_service.py\", line 229, in send\n    response.status_code, error_message, http_response=response)\nibm_cloud_sdk_core.api_exception.ApiException: Error: Forbidden, Code: 403\n 76%|\u2588\u2588\u2588\u2588\u2588\u2588\u2588\u258c  | 4058/5347 [28:16<05:56,  3.62it/s]ERROR:root:Forbidden\nTraceback (most recent call last):\n  File \"/opt/conda/envs/Python36/lib/python3.6/site-packages/ibm_cloud_sdk_core/base_service.py\", line 229, in send\n    response.status_code, error_message, http_response=response)\nibm_cloud_sdk_core.api_exception.ApiException: Error: Forbidden, Code: 403\n 76%|\u2588\u2588\u2588\u2588\u2588\u2588\u2588\u258c  | 4059/5347 [28:17<06:51,  3.13it/s]ERROR:root:Forbidden\nTraceback (most recent call last):\n  File \"/opt/conda/envs/Python36/lib/python3.6/site-packages/ibm_cloud_sdk_core/base_service.py\", line 229, in send\n    response.status_code, error_message, http_response=response)\nibm_cloud_sdk_core.api_exception.ApiException: Error: Forbidden, Code: 403\n 76%|\u2588\u2588\u2588\u2588\u2588\u2588\u2588\u258c  | 4060/5347 [28:17<07:26,  2.88it/s]ERROR:root:Forbidden\nTraceback (most recent call last):\n  File \"/opt/conda/envs/Python36/lib/python3.6/site-packages/ibm_cloud_sdk_core/base_service.py\", line 229, in send\n    response.status_code, error_message, http_response=response)\nibm_cloud_sdk_core.api_exception.ApiException: Error: Forbidden, Code: 403\n 76%|\u2588\u2588\u2588\u2588\u2588\u2588\u2588\u258c  | 4061/5347 [28:18<07:57,  2.69it/s]ERROR:root:Forbidden\nTraceback (most recent call last):\n  File \"/opt/conda/envs/Python36/lib/python3.6/site-packages/ibm_cloud_sdk_core/base_service.py\", line 229, in send\n    response.status_code, error_message, http_response=response)\nibm_cloud_sdk_core.api_exception.ApiException: Error: Forbidden, Code: 403\n 76%|\u2588\u2588\u2588\u2588\u2588\u2588\u2588\u258c  | 4062/5347 [28:18<08:19,  2.57it/s]ERROR:root:Forbidden\nTraceback (most recent call last):\n  File \"/opt/conda/envs/Python36/lib/python3.6/site-packages/ibm_cloud_sdk_core/base_service.py\", line 229, in send\n    response.status_code, error_message, http_response=response)\nibm_cloud_sdk_core.api_exception.ApiException: Error: Forbidden, Code: 403\n 76%|\u2588\u2588\u2588\u2588\u2588\u2588\u2588\u258c  | 4063/5347 [28:18<08:27,  2.53it/s]ERROR:root:Forbidden\nTraceback (most recent call last):\n  File \"/opt/conda/envs/Python36/lib/python3.6/site-packages/ibm_cloud_sdk_core/base_service.py\", line 229, in send\n    response.status_code, error_message, http_response=response)\nibm_cloud_sdk_core.api_exception.ApiException: Error: Forbidden, Code: 403\n 76%|\u2588\u2588\u2588\u2588\u2588\u2588\u2588\u258c  | 4064/5347 [28:19<08:43,  2.45it/s]ERROR:root:Forbidden\nTraceback (most recent call last):\n  File \"/opt/conda/envs/Python36/lib/python3.6/site-packages/ibm_cloud_sdk_core/base_service.py\", line 229, in send\n    response.status_code, error_message, http_response=response)\nibm_cloud_sdk_core.api_exception.ApiException: Error: Forbidden, Code: 403\n 76%|\u2588\u2588\u2588\u2588\u2588\u2588\u2588\u258c  | 4065/5347 [28:19<07:19,  2.92it/s]", "name": "stderr"}]}, {"metadata": {}, "cell_type": "code", "source": "", "execution_count": null, "outputs": []}], "metadata": {"kernelspec": {"name": "python3", "display_name": "Python 3.6", "language": "python"}, "language_info": {"name": "python", "version": "3.6.9", "mimetype": "text/x-python", "codemirror_mode": {"name": "ipython", "version": 3}, "pygments_lexer": "ipython3", "nbconvert_exporter": "python", "file_extension": ".py"}}, "nbformat": 4, "nbformat_minor": 1}